Workbook

Sheet Table 1
A1: NHCL SCF
A2: 10 | B2: =VLOOKUP(A2,'SCF Reference'!A:B,2,FALSE) -> CT | D2: 104 | E2: =VLOOKUP(D2,'SCF Reference'!A:B,2,FALSE) -> NY | G2: 225 | H2: =VLOOKUP(G2,'SCF Reference'!A:B,2,FALSE) -> VA | J2: 302 | K2: =VLOOKUP(J2,'SCF Reference'!A:B,2,FALSE) -> GA | M2: 401 | N2: =VLOOKUP(M2,'SCF Reference'!A:B,2,FALSE) -> KY | P2: 503 | Q2: =VLOOKUP(P2,'SCF Reference'!A:B,2,FALSE) -> IA | S2: 600 | T2: =VLOOKUP(S2,'SCF Reference'!A:B,2,FALSE) -> IL | V2: 719 | W2: =VLOOKUP('Table 1'!V2,'SCF Reference'!A:B,2,FALSE) -> AR | Y2: 800 | Z2: =VLOOKUP(Y2,'SCF Reference'!A:B,2,FALSE) -> CO | AB2: 902 | AC2: =VLOOKUP('Table 1'!AB27,'SCF Reference'!A:B,2,FALSE) -> OR
A3: 11 | B3: =VLOOKUP(A3,'SCF Reference'!A:B,2,FALSE) -> CT | D3: 105 | E3: =VLOOKUP(D3,'SCF Reference'!A:B,2,FALSE) -> NY | G3: 232 | H3: =VLOOKUP(G3,'SCF Reference'!A:B,2,FALSE) -> VA | J3: 306 | K3: =VLOOKUP(J3,'SCF Reference'!A:B,2,FALSE) -> GA | M3: 402 | N3: =VLOOKUP(M3,'SCF Reference'!A:B,2,FALSE) -> KY | P3: 507 | Q3: =VLOOKUP(P3,'SCF Reference'!A:B,2,FALSE) -> IA | S3: 604 | T3: =VLOOKUP(S3,'SCF Reference'!A:B,2,FALSE) -> IL | V3: 720 | W3: =VLOOKUP('Table 1'!V23,'SCF Reference'!A:B,2,FALSE) -> TX | Y3: 809 | Z3: =VLOOKUP(Y3,'SCF Reference'!A:B,2,FALSE) -> CO | AB3: 903 | AC3: =VLOOKUP('Table 1'!AB2,'SCF Reference'!A:B,2,FALSE) -> CA
A4: 12 | B4: =VLOOKUP(A4,'SCF Reference'!A:B,2,FALSE) -> CT | D4: 109 | E4: =VLOOKUP(D4,'SCF Reference'!A:B,2,FALSE) -> NY | G4: 236 | H4: =VLOOKUP(G4,'SCF Reference'!A:B,2,FALSE) -> VA | J4: 308 | K4: =VLOOKUP(J4,'SCF Reference'!A:B,2,FALSE) -> GA | M4: 420 | N4: =VLOOKUP(M4,'SCF Reference'!A:B,2,FALSE) -> IN | P4: 523 | Q4: =VLOOKUP(P4,'SCF Reference'!A:B,2,FALSE) -> IA | S4: 606 | T4: =VLOOKUP(S4,'SCF Reference'!A:B,2,FALSE) -> IL | V4: 721 | W4: =VLOOKUP('Table 1'!V26,'SCF Reference'!A:B,2,FALSE) -> TX | Y4: 810 | Z4: =VLOOKUP(Y4,'SCF Reference'!A:B,2,FALSE) -> CO | AB4: 920 | AC4: =VLOOKUP('Table 1'!AB3,'SCF Reference'!A:B,2,FALSE) -> CA
A5: 13 | B5: =VLOOKUP(A5,'SCF Reference'!A:B,2,FALSE) -> MA | D5: 112 | E5: =VLOOKUP(D5,'SCF Reference'!A:B,2,FALSE) -> NY | G5: 238 | H5: =VLOOKUP(G5,'SCF Reference'!A:B,2,FALSE) -> VA | J5: 309 | K5: =VLOOKUP(J5,'SCF Reference'!A:B,2,FALSE) -> GA | M5: 422 | N5: =VLOOKUP(M5,'SCF Reference'!A:B,2,FALSE) -> TN | P5: 532 | Q5: =VLOOKUP(P5,'SCF Reference'!A:B,2,FALSE) -> WI | S5: 608 | T5: =VLOOKUP(S5,'SCF Reference'!A:B,2,FALSE) -> IL | V5: 722 | W5: =VLOOKUP('Table 1'!V3,'SCF Reference'!A:B,2,FALSE) -> AR | Y5: 812 | Z5: =VLOOKUP(Y5,'SCF Reference'!A:B,2,FALSE) -> CO | AB5: 922 | AC5: =VLOOKUP('Table 1'!AB4,'SCF Reference'!A:B,2,FALSE) -> CA
A6: 14 | B6: =VLOOKUP(A6,'SCF Reference'!A:B,2,FALSE) -> MA | D6: 113 | E6: =VLOOKUP(D6,'SCF Reference'!A:B,2,FALSE) -> NY | G6: 241 | H6: =VLOOKUP(G6,'SCF Reference'!A:B,2,FALSE) -> VA | J6: 310 | K6: =VLOOKUP(J6,'SCF Reference'!A:B,2,FALSE) -> GA | M6: 431 | N6: =VLOOKUP(M6,'SCF Reference'!A:B,2,FALSE) -> OH | P6: 535 | Q6: =VLOOKUP(P6,'SCF Reference'!A:B,2,FALSE) -> WI | S6: 609 | T6: =VLOOKUP(S6,'SCF Reference'!A:B,2,FALSE) -> IL | V6: 723 | W6: =VLOOKUP('Table 1'!V4,'SCF Reference'!A:B,2,FALSE) -> AR | Y6: 814 | Z6: =VLOOKUP(Y6,'SCF Reference'!A:B,2,FALSE) -> CO | AB6: 923 | AC6: =VLOOKUP('Table 1'!AB5,'SCF Reference'!A:B,2,FALSE) -> CA
A7: 17 | B7: =VLOOKUP(A7,'SCF Reference'!A:B,2,FALSE) -> MA | D7: 114 | E7: =VLOOKUP(D7,'SCF Reference'!A:B,2,FALSE) -> NY | G7: 245 | H7: =VLOOKUP(G7,'SCF Reference'!A:B,2,FALSE) -> VA | J7: 312 | K7: =VLOOKUP(J7,'SCF Reference'!A:B,2,FALSE) -> GA | M7: 435 | N7: =VLOOKUP(M7,'SCF Reference'!A:B,2,FALSE) -> OH | P7: 554 | Q7: =VLOOKUP(P7,'SCF Reference'!A:B,2,FALSE) -> MN | S7: 611 | T7: =VLOOKUP(S7,'SCF Reference'!A:B,2,FALSE) -> IL | V7: 724 | W7: =VLOOKUP('Table 1'!V29,'SCF Reference'!A:B,2,FALSE) -> TX | Y7: 820 | Z7: =VLOOKUP(Y7,'SCF Reference'!A:B,2,FALSE) -> WY | AB7: 924 | AC7: =VLOOKUP('Table 1'!AB6,'SCF Reference'!A:B,2,FALSE) -> CA
A8: 18 | B8: =VLOOKUP(A8,'SCF Reference'!A:B,2,FALSE) -> MA | D8: 115 | E8: =VLOOKUP(D8,'SCF Reference'!A:B,2,FALSE) -> NY | G8: 254 | H8: =VLOOKUP(G8,'SCF Reference'!A:B,2,FALSE) -> PA | J8: 315 | K8: =VLOOKUP(J8,'SCF Reference'!A:B,2,FALSE) -> FL | M8: 436 | N8: =VLOOKUP(M8,'SCF Reference'!A:B,2,FALSE) -> OH | P8: 560 | Q8: =VLOOKUP(P8,'SCF Reference'!A:B,2,FALSE) -> MN | S8: 613 | T8: =VLOOKUP(S8,'SCF Reference'!A:B,2,FALSE) -> IL | V8: 727 | W8: =VLOOKUP('Table 1'!#REF!,'SCF Reference'!A:B,2,FALSE) -> #REF! | Y8: 826 | Z8: =VLOOKUP(Y8,'SCF Reference'!A:B,2,FALSE) -> WY | AB8: 925 | AC8: =VLOOKUP('Table 1'!AB7,'SCF Reference'!A:B,2,FALSE) -> CA
A9: 19 | B9: =VLOOKUP(A9,'SCF Reference'!A:B,2,FALSE) -> MA | D9: 116 | E9: =VLOOKUP(D9,'SCF Reference'!A:B,2,FALSE) -> NY | G9: 292 | H9: =VLOOKUP(G9,'SCF Reference'!A:B,2,FALSE) -> SC | J9: 316 | K9: =VLOOKUP(J9,'SCF Reference'!A:B,2,FALSE) -> FL | M9: 441 | N9: =VLOOKUP(M9,'SCF Reference'!A:B,2,FALSE) -> OH | P9: 581 | Q9: =VLOOKUP(P9,'SCF Reference'!A:B,2,FALSE) -> ND | S9: 615 | T9: =VLOOKUP(S9,'SCF Reference'!A:B,2,FALSE) -> IL | V9: 729 | W9: =VLOOKUP('Table 1'!V5,'SCF Reference'!A:B,2,FALSE) -> AR | Y9: 832 | Z9: =VLOOKUP(Y9,'SCF Reference'!A:B,2,FALSE) -> ID | AB9: 932 | AC9: =VLOOKUP('Table 1'!AB8,'SCF Reference'!A:B,2,FALSE) -> CA
A10: 21 | B10: =VLOOKUP(A10,'SCF Reference'!A:B,2,FALSE) -> MA | D10: 117 | E10: =VLOOKUP(D10,'SCF Reference'!A:B,2,FALSE) -> NY | G10: 294 | H10: =VLOOKUP(G10,'SCF Reference'!A:B,2,FALSE) -> SC | J10: 317 | K10: =VLOOKUP(J10,'SCF Reference'!A:B,2,FALSE) -> FL | M10: 443 | N10: =VLOOKUP(M10,'SCF Reference'!A:B,2,FALSE) -> OH | P10: 583 | Q10: =VLOOKUP(P10,'SCF Reference'!A:B,2,FALSE) -> ND | S10: 616 | T10: =VLOOKUP(S10,'SCF Reference'!A:B,2,FALSE) -> IL | V10: 730 | W10: =VLOOKUP('Table 1'!V30,'SCF Reference'!A:B,2,FALSE) -> TX | Y10: 833 | Z10: =VLOOKUP(Y10,'SCF Reference'!A:B,2,FALSE) -> ID | AB10: 933 | AC10: =VLOOKUP('Table 1'!AB9,'SCF Reference'!A:B,2,FALSE) -> CA
A11: 23 | B11: =VLOOKUP(A11,'SCF Reference'!A:B,2,FALSE) -> MA | D11: 121 | E11: =VLOOKUP(D11,'SCF Reference'!A:B,2,FALSE) -> NY | G11: 295 | H11: =VLOOKUP(G11,'SCF Reference'!A:B,2,FALSE) -> SC | J11: 319 | K11: =VLOOKUP(J11,'SCF Reference'!A:B,2,FALSE) -> GA | M11: 444 | N11: =VLOOKUP(M11,'SCF Reference'!A:B,2,FALSE) -> OH | P11: 588 | Q11: =VLOOKUP(P11,'SCF Reference'!A:B,2,FALSE) -> ND | S11: 622 | T11: =VLOOKUP(S11,'SCF Reference'!A:B,2,FALSE) -> MO | V11: 731 | W11: =VLOOKUP('Table 1'!V6,'SCF Reference'!A:B,2,FALSE) -> TN | Y11: 834 | Z11: =VLOOKUP(Y11,'SCF Reference'!A:B,2,FALSE) -> ID | AB11: 935 | AC11: =VLOOKUP('Table 1'!AB10,'SCF Reference'!A:B,2,FALSE) -> CA
A12: 26 | B12: =VLOOKUP(A12,'SCF Reference'!A:B,2,FALSE) -> RI | D12: 126 | E12: =VLOOKUP(D12,'SCF Reference'!A:B,2,FALSE) -> NY | G12: 296 | H12: =VLOOKUP(G12,'SCF Reference'!A:B,2,FALSE) -> SC | J12: 321 | K12: =VLOOKUP(J12,'SCF Reference'!A:B,2,FALSE) -> FL | M12: 445 | N12: =VLOOKUP(M12,'SCF Reference'!A:B,2,FALSE) -> OH | S12: 631 | T12: =VLOOKUP(S12,'SCF Reference'!A:B,2,FALSE) -> MO | V12: 740 | W12: =VLOOKUP('Table 1'!V7,'SCF Reference'!A:B,2,FALSE) -> TN | Y12: 835 | Z12: =VLOOKUP(Y12,'SCF Reference'!A:B,2,FALSE) -> WA | AB12: 936 | AC12: =VLOOKUP('Table 1'!AB24,'SCF Reference'!A:B,2,FALSE) -> OR
A13: 27 | B13: =VLOOKUP(A13,'SCF Reference'!A:B,2,FALSE) -> RI | D13: 130 | E13: =VLOOKUP(D13,'SCF Reference'!A:B,2,FALSE) -> NY | G13: 298 | H13: =VLOOKUP(G13,'SCF Reference'!A:B,2,FALSE) -> GA | J13: 324 | K13: =VLOOKUP(J13,'SCF Reference'!A:B,2,FALSE) -> FL | M13: 448 | N13: =VLOOKUP(M13,'SCF Reference'!A:B,2,FALSE) -> OH | S13: 637 | T13: =VLOOKUP(S13,'SCF Reference'!A:B,2,FALSE) -> MO | V13: 743 | W13: =VLOOKUP('Table 1'!V8,'SCF Reference'!A:B,2,FALSE) -> AR | Y13: 836 | Z13: =VLOOKUP(Y13,'SCF Reference'!A:B,2,FALSE) -> ID | AB13: 937 | AC13: =VLOOKUP('Table 1'!AB11,'SCF Reference'!A:B,2,FALSE) -> CA
A14: 28 | B14: =VLOOKUP(A14,'SCF Reference'!A:B,2,FALSE) -> RI | D14: 132 | E14: =VLOOKUP(D14,'SCF Reference'!A:B,2,FALSE) -> NY | J14: 325 | K14: =VLOOKUP(J14,'SCF Reference'!A:B,2,FALSE) -> FL | M14: 449 | N14: =VLOOKUP(M14,'SCF Reference'!A:B,2,FALSE) -> OH | S14: 639 | T14: =VLOOKUP(S14,'SCF Reference'!A:B,2,FALSE) -> MO | V14: 744 | W14: =VLOOKUP('Table 1'!V9,'SCF Reference'!A:B,2,FALSE) -> AR | Y14: 837 | Z14: =VLOOKUP(Y14,'SCF Reference'!A:B,2,FALSE) -> ID | AB14: 939 | AC14: =VLOOKUP('Table 1'!AB12,'SCF Reference'!A:B,2,FALSE) -> CA
A15: 40 | B15: =VLOOKUP(A15,'SCF Reference'!A:B,2,FALSE) -> ME | D15: 139 | E15: =VLOOKUP(D15,'SCF Reference'!A:B,2,FALSE) -> NY | J15: 326 | K15: =VLOOKUP(J15,'SCF Reference'!A:B,2,FALSE) -> FL | M15: 452 | N15: =VLOOKUP(M15,'SCF Reference'!A:B,2,FALSE) -> OH | S15: 648 | T15: =VLOOKUP(S15,'SCF Reference'!A:B,2,FALSE) -> MO | V15: 749 | W15: =VLOOKUP('Table 1'!V10,'SCF Reference'!A:B,2,FALSE) -> OK | Y15: 838 | Z15: =VLOOKUP(Y15,'SCF Reference'!A:B,2,FALSE) -> WA | AB15: 945 | AC15: =VLOOKUP('Table 1'!AB13,'SCF Reference'!A:B,2,FALSE) -> CA
A16: 41 | B16: =VLOOKUP(A16,'SCF Reference'!A:B,2,FALSE) -> ME | D16: 142 | E16: =VLOOKUP(D16,'SCF Reference'!A:B,2,FALSE) -> NY | J16: 327 | K16: =VLOOKUP(J16,'SCF Reference'!A:B,2,FALSE) -> FL | M16: 454 | N16: =VLOOKUP(M16,'SCF Reference'!A:B,2,FALSE) -> OH | S16: 656 | T16: =VLOOKUP(S16,'SCF Reference'!A:B,2,FALSE) -> MO | V16: 750 | W16: =VLOOKUP('Table 1'!V11,'SCF Reference'!A:B,2,FALSE) -> OK | Y16: 851 | Z16: =VLOOKUP(Y16,'SCF Reference'!A:B,2,FALSE) -> AZ | AB16: 952 | AC16: =VLOOKUP('Table 1'!AB14,'SCF Reference'!A:B,2,FALSE) -> CA
A17: 42 | B17: =VLOOKUP(A17,'SCF Reference'!A:B,2,FALSE) -> ME | D17: 143 | E17: =VLOOKUP(D17,'SCF Reference'!A:B,2,FALSE) -> NY | J17: 329 | K17: =VLOOKUP(J17,'SCF Reference'!A:B,2,FALSE) -> FL | M17: 456 | N17: =VLOOKUP(M17,'SCF Reference'!A:B,2,FALSE) -> OH | S17: 658 | T17: =VLOOKUP(S17,'SCF Reference'!A:B,2,FALSE) -> MO | V17: 751 | W17: =VLOOKUP('Table 1'!V12,'SCF Reference'!A:B,2,FALSE) -> OK | Y17: 860 | Z17: =VLOOKUP(Y17,'SCF Reference'!A:B,2,FALSE) -> AZ | AB17: 953 | AC17: =VLOOKUP('Table 1'!AB15,'SCF Reference'!A:B,2,FALSE) -> CA
A18: 46 | B18: =VLOOKUP(A18,'SCF Reference'!A:B,2,FALSE) -> ME | D18: 146 | E18: =VLOOKUP(D18,'SCF Reference'!A:B,2,FALSE) -> NY | J18: 335 | K18: =VLOOKUP(J18,'SCF Reference'!A:B,2,FALSE) -> FL | M18: 458 | N18: =VLOOKUP(M18,'SCF Reference'!A:B,2,FALSE) -> OH | V18: 754 | W18: =VLOOKUP('Table 1'!V13,'SCF Reference'!A:B,2,FALSE) -> OK | Y18: 863 | Z18: =VLOOKUP(Y18,'SCF Reference'!A:B,2,FALSE) -> AZ | AB18: 955 | AC18: =VLOOKUP('Table 1'!AB16,'SCF Reference'!A:B,2,FALSE) -> CA
A19: 47 | B19: =VLOOKUP(A19,'SCF Reference'!A:B,2,FALSE) -> ME | D19: 150 | E19: =VLOOKUP(D19,'SCF Reference'!A:B,2,FALSE) -> PA | J19: 338 | K19: =VLOOKUP(J19,'SCF Reference'!A:B,2,FALSE) -> FL | M19: 462 | N19: =VLOOKUP(M19,'SCF Reference'!A:B,2,FALSE) -> IN | V19: 756 | W19: =VLOOKUP('Table 1'!V27,'SCF Reference'!A:B,2,FALSE) -> TX | Y19: 864 | Z19: =VLOOKUP(Y19,'SCF Reference'!A:B,2,FALSE) -> NV | AB19: 959 | AC19: =VLOOKUP('Table 1'!AB28,'SCF Reference'!A:B,2,FALSE) -> OR
A20: 60 | B20: =VLOOKUP(A20,'SCF Reference'!A:B,2,FALSE) -> CT | D20: 151 | E20: =VLOOKUP(D20,'SCF Reference'!A:B,2,FALSE) -> PA | J20: 344 | K20: =VLOOKUP(J20,'SCF Reference'!A:B,2,FALSE) -> FL | M20: 463 | N20: =VLOOKUP(M20,'SCF Reference'!A:B,2,FALSE) -> IN | V20: 757 | W20: =VLOOKUP('Table 1'!V14,'SCF Reference'!A:B,2,FALSE) -> OK | Y20: 890 | Z20: =VLOOKUP(Y20,'SCF Reference'!A:B,2,FALSE) -> NV | AB20: 960 | AC20: =VLOOKUP('Table 1'!AB17,'SCF Reference'!A:B,2,FALSE) -> CA
A21: 61 | B21: =VLOOKUP(A21,'SCF Reference'!A:B,2,FALSE) -> CT | D21: 152 | E21: =VLOOKUP(D21,'SCF Reference'!A:B,2,FALSE) -> PA | J21: 346 | K21: =VLOOKUP(J21,'SCF Reference'!A:B,2,FALSE) -> FL | M21: 465 | N21: =VLOOKUP(M21,'SCF Reference'!A:B,2,FALSE) -> IN | V21: 759 | W21: =VLOOKUP('Table 1'!V28,'SCF Reference'!A:B,2,FALSE) -> TX | Y21: 891 | Z21: =VLOOKUP(Y21,'SCF Reference'!A:B,2,FALSE) -> NV | AB21: 961 | AC21: =VLOOKUP('Table 1'!AB18,'SCF Reference'!A:B,2,FALSE) -> CA
A22: 67 | B22: =VLOOKUP(A22,'SCF Reference'!A:B,2,FALSE) -> CT | D22: 153 | E22: =VLOOKUP(D22,'SCF Reference'!A:B,2,FALSE) -> PA | J22: 347 | K22: =VLOOKUP(J22,'SCF Reference'!A:B,2,FALSE) -> FL | M22: 473 | N22: =VLOOKUP(M22,'SCF Reference'!A:B,2,FALSE) -> IN | V22: 763 | W22: =VLOOKUP('Table 1'!V15,'SCF Reference'!A:B,2,FALSE) -> OK | Y22: 893 | Z22: =VLOOKUP(Y22,'SCF Reference'!A:B,2,FALSE) -> NV | AB22: 967 | AC22: =VLOOKUP('Table 1'!AB19,'SCF Reference'!A:B,2,FALSE) -> CA
A23: 70 | B23: =VLOOKUP(A23,'SCF Reference'!A:B,2,FALSE) -> NJ | D23: 154 | E23: =VLOOKUP(D23,'SCF Reference'!A:B,2,FALSE) -> PA | J23: 350 | K23: =VLOOKUP(J23,'SCF Reference'!A:B,2,FALSE) -> AL | M23: 490 | N23: =VLOOKUP(M23,'SCF Reference'!A:B,2,FALSE) -> MI | V23: 765 | W23: =VLOOKUP('Table 1'!V25,'SCF Reference'!A:B,2,FALSE) -> TX | Y23: 894 | Z23: =VLOOKUP(Y23,'SCF Reference'!A:B,2,FALSE) -> NV | AB23: 970 | AC23: =VLOOKUP('Table 1'!AB20,'SCF Reference'!A:B,2,FALSE) -> CA
A24: 71 | B24: =VLOOKUP(A24,'SCF Reference'!A:B,2,FALSE) -> NJ | D24: 156 | E24: =VLOOKUP(D24,'SCF Reference'!A:B,2,FALSE) -> PA | J24: 354 | K24: =VLOOKUP(J24,'SCF Reference'!A:B,2,FALSE) -> AL | V24: 770 | W24: =VLOOKUP('Table 1'!V16,'SCF Reference'!A:B,2,FALSE) -> TX | Y24: 895 | Z24: =VLOOKUP(Y24,'SCF Reference'!A:B,2,FALSE) -> NV | AB24: 971 | AC24: =VLOOKUP('Table 1'!AB21,'SCF Reference'!A:B,2,FALSE) -> NV
A25: 72 | B25: =VLOOKUP(A25,'SCF Reference'!A:B,2,FALSE) -> NJ | D25: 165 | E25: =VLOOKUP(D25,'SCF Reference'!A:B,2,FALSE) -> PA | J25: 356 | K25: =VLOOKUP(J25,'SCF Reference'!A:B,2,FALSE) -> AL | V25: 772 | W25: =VLOOKUP('Table 1'!V17,'SCF Reference'!A:B,2,FALSE) -> TX | Y25: 897 | Z25: =VLOOKUP(Y25,'SCF Reference'!A:B,2,FALSE) -> NV | AB25: 973 | AC25: =VLOOKUP('Table 1'!AB25,'SCF Reference'!A:B,2,FALSE) -> OR
A26: 77 | B26: =VLOOKUP(A26,'SCF Reference'!A:B,2,FALSE) -> NJ | D26: 171 | E26: =VLOOKUP(D26,'SCF Reference'!A:B,2,FALSE) -> PA | J26: 357 | K26: =VLOOKUP(J26,'SCF Reference'!A:B,2,FALSE) -> AL | V26: 776 | W26: =VLOOKUP('Table 1'!V18,'SCF Reference'!A:B,2,FALSE) -> TX | AB26: 974 | AC26: =VLOOKUP('Table 1'!AB22,'SCF Reference'!A:B,2,FALSE) -> HI
A27: 80 | B27: =VLOOKUP(A27,'SCF Reference'!A:B,2,FALSE) -> NJ | D27: 172 | E27: =VLOOKUP(D27,'SCF Reference'!A:B,2,FALSE) -> PA | J27: 358 | K27: =VLOOKUP(J27,'SCF Reference'!A:B,2,FALSE) -> AL | V27: 784 | W27: =VLOOKUP('Table 1'!V20,'SCF Reference'!A:B,2,FALSE) -> TX | AB27: 975 | AC27: =VLOOKUP('Table 1'!AB23,'SCF Reference'!A:B,2,FALSE) -> OR
A28: 82 | B28: =VLOOKUP(A28,'SCF Reference'!A:B,2,FALSE) -> NJ | D28: 176 | E28: =VLOOKUP(D28,'SCF Reference'!A:B,2,FALSE) -> PA | J28: 359 | K28: =VLOOKUP(J28,'SCF Reference'!A:B,2,FALSE) -> AL | V28: 790 | W28: =VLOOKUP('Table 1'!V24,'SCF Reference'!A:B,2,FALSE) -> TX | AB28: 978 | AC28: =VLOOKUP('Table 1'!AB26,'SCF Reference'!A:B,2,FALSE) -> OR
A29: 83 | B29: =VLOOKUP(A29,'SCF Reference'!A:B,2,FALSE) -> NJ | D29: 177 | E29: =VLOOKUP(D29,'SCF Reference'!A:B,2,FALSE) -> PA | J29: 360 | K29: =VLOOKUP(J29,'SCF Reference'!A:B,2,FALSE) -> AL | V29: 791 | W29: =VLOOKUP('Table 1'!V25,'SCF Reference'!A:B,2,FALSE) -> TX
A30: 84 | B30: =VLOOKUP(A30,'SCF Reference'!A:B,2,FALSE) -> NJ | D30: 181 | E30: =VLOOKUP(D30,'SCF Reference'!A:B,2,FALSE) -> PA | J30: 361 | K30: =VLOOKUP(J30,'SCF Reference'!A:B,2,FALSE) -> AL | V30: 799 | W30: =VLOOKUP('Table 1'!V22,'SCF Reference'!A:B,2,FALSE) -> TX
A31: 85 | B31: =VLOOKUP(A31,'SCF Reference'!A:B,2,FALSE) -> NJ | D31: 182 | E31: =VLOOKUP(D31,'SCF Reference'!A:B,2,FALSE) -> PA | J31: 362 | K31: =VLOOKUP(J31,'SCF Reference'!A:B,2,FALSE) -> AL
A32: 86 | B32: =VLOOKUP(A32,'SCF Reference'!A:B,2,FALSE) -> NJ | D32: 183 | E32: =VLOOKUP(D32,'SCF Reference'!A:B,2,FALSE) -> PA | J32: 365 | K32: =VLOOKUP(J32,'SCF Reference'!A:B,2,FALSE) -> AL
D33: 187 | E33: =VLOOKUP(D33,'SCF Reference'!A:B,2,FALSE) -> PA | J33: 366 | K33: =VLOOKUP(J33,'SCF Reference'!A:B,2,FALSE) -> AL
D34: 189 | E34: =VLOOKUP(D34,'SCF Reference'!A:B,2,FALSE) -> PA | J34: 373 | K34: =VLOOKUP(J34,'SCF Reference'!A:B,2,FALSE) -> TN
D35: 190 | E35: =VLOOKUP(D35,'SCF Reference'!A:B,2,FALSE) -> PA | J35: 377 | K35: =VLOOKUP(J35,'SCF Reference'!A:B,2,FALSE) -> TN
D36: 191 | E36: =VLOOKUP(D36,'SCF Reference'!A:B,2,FALSE) -> PA | J36: 378 | K36: =VLOOKUP(J36,'SCF Reference'!A:B,2,FALSE) -> TN
D37: 197 | E37: =VLOOKUP(D37,'SCF Reference'!A:B,2,FALSE) -> DE | J37: 381 | K37: =VLOOKUP(J37,'SCF Reference'!A:B,2,FALSE) -> TN
D38: 199 | E38: =VLOOKUP(D38,'SCF Reference'!A:B,2,FALSE) -> DE | J38: 382 | K38: =VLOOKUP(J38,'SCF Reference'!A:B,2,FALSE) -> TN
J39: 383 | K39: =VLOOKUP(J39,'SCF Reference'!A:B,2,FALSE) -> TN
J40: 386 | K40: =VLOOKUP(J40,'SCF Reference'!A:B,2,FALSE) -> TN
...

Sheet SCF Reference
A1: 5 | B1: NY
A2: 6 | B2: PR
A3: 7 | B3: PR
A4: 8 | B4: PR
A5: 9 | B5: PR
A6: 10 | B6: CT
A7: 11 | B7: CT
A8: 12 | B8: CT
A9: 13 | B9: MA
A10: 14 | B10: MA
A11: 15 | B11: MA
A12: 16 | B12: MA
... A931: 999 | B931: AK

Sheet Sheet1
A1: 10 | B1: CT
A2: 11 | B2: CT
A3: 12 | B3: CT
A4: 13 | B4: MA
A5: 14 | B5: MA
A6: 17 | B6: MA
A7: 18 | B7: MA
A8: 19 | B8: MA
A9: 21 | B9: MA
A10: 23 | B10: MA
A11: 26 | B11: RI
A12: 27 | B12: RI
... A260: 978 | B260: OR
