Workbook
Name Account_FullBillingAddress: Sheet1!$B$14
Name Account_Name: Sheet1!$C$11
Name CreditAmount: #REF!
Name CreditAmount1: Credit!$C$1:$C$100
Name Creditamount2: Credit!$C$2:$C$251
Name CreditDate: #REF!
Name CreditDate1: Credit!$A$1:$A$100
Name Creditdate2: Credit!$C$2:$C$251
Name creditdate3: Credit!$B$2:$B$350
Name CreditTable: #REF!
Name GrandTotal: Totals!$L$5
Name Member1_Name: Sheet1!$B$13
Name Member2_Name: Sheet1!$C$13
Name PaymentAmount: #REF!
Name PaymentAmount1: Payment!$C$2:$C$1600
Name PaymentCheck: Payment!$F$1:$F$1444
Name PaymentCheck1: Payment!$F$2:$F$1673
Name PaymentDate: #REF!
Name PaymentDate1: Payment!$B$2:$B$1600
Name PaymentTable: #REF!
Name Sort: Totals!$O$2:$Q$3487
Name Sort\: Totals!$O$2:$P$3487
Name TotalCredit: #REF!
Name TotalPayment: #REF!

Sheet Credit

Sheet Payment

Sheet Totals
A1: {=creditdate3} -> 0 | B1: {=Creditamount2*-1} -> 0 | C1: =Credit!F2 -> 0 | D1: {=PaymentDate1} -> 0 | E1: {=PaymentAmount1} -> 0 | F1: =Payment!F2 -> 0 | H1: {=IF(IF(ROW()<=COUNTA(D:D), INDEX(D:D,ROW()), IF(ROW()>COUNTA(A:D), "", INDEX(A:A,ROW()-COUNTA(D:D))))=0, "", IF(ROW()<=COUNTA(D:D), INDEX(D:D,ROW()), IF(ROW()>COUNTA(A:D), "", INDEX(A:A,ROW()-COUNTA(D:D)))))} | I1: {=IF(IF(ROW()<=COUNTA(E:E), INDEX(E:E,ROW()), IF(ROW()>COUNTA(B:E), "", INDEX(B:B,ROW()-COUNTA(E:E))))=0, "", IF(ROW()<=COUNTA(E:E), INDEX(E:E,ROW()), IF(ROW()>COUNTA(B:E), "", INDEX(B:B,ROW()-COUNTA(E:E)))))} | J1: {=IF(IF(ROW()<=COUNTA(F:F), INDEX(F:F,ROW()), IF(ROW()>COUNTA(C:F), "", INDEX(C:C,ROW()-COUNTA(F:F))))=0, "", IF(ROW()<=COUNTA(F:F), INDEX(F:F,ROW()), IF(ROW()>COUNTA(C:F), "", INDEX(C:C,ROW()-COUNTA(F:F)))))}
A2: 0 | B2: 0 | C2: =Credit!F3 -> 0 | D2: 0 | E2: 0 | F2: =Payment!F3 -> 0 | H2: {=IF(IF(ROW()<=COUNTA(D:D), INDEX(D:D,ROW()), IF(ROW()>COUNTA(A:D), "", INDEX(A:A,ROW()-COUNTA(D:D))))=0, "", IF(ROW()<=COUNTA(D:D), INDEX(D:D,ROW()), IF(ROW()>COUNTA(A:D), "", INDEX(A:A,ROW()-COUNTA(D:D)))))} | I2: {=IF(IF(ROW()<=COUNTA(E:E), INDEX(E:E,ROW()), IF(ROW()>COUNTA(B:E), "", INDEX(B:B,ROW()-COUNTA(E:E))))=0, "", IF(ROW()<=COUNTA(E:E), INDEX(E:E,ROW()), IF(ROW()>COUNTA(B:E), "", INDEX(B:B,ROW()-COUNTA(E:E)))))} | J2: {=IF(IF(ROW()<=COUNTA(F:F), INDEX(F:F,ROW()), IF(ROW()>COUNTA(C:F), "", INDEX(C:C,ROW()-COUNTA(F:F))))=0, "", IF(ROW()<=COUNTA(F:F), INDEX(F:F,ROW()), IF(ROW()>COUNTA(C:F), "", INDEX(C:C,ROW()-COUNTA(F:F)))))} | O2: {=_xlfn._xlws.SORT(Totals!$H$1:$J$3486)}
A3: 0 | B3: 0 | C3: =Credit!F4 -> 0 | D3: 0 | E3: 0 | F3: =Payment!F4 -> 0 | H3: {=IF(IF(ROW()<=COUNTA(D:D), INDEX(D:D,ROW()), IF(ROW()>COUNTA(A:D), "", INDEX(A:A,ROW()-COUNTA(D:D))))=0, "", IF(ROW()<=COUNTA(D:D), INDEX(D:D,ROW()), IF(ROW()>COUNTA(A:D), "", INDEX(A:A,ROW()-COUNTA(D:D)))))} | I3: {=IF(IF(ROW()<=COUNTA(E:E), INDEX(E:E,ROW()), IF(ROW()>COUNTA(B:E), "", INDEX(B:B,ROW()-COUNTA(E:E))))=0, "", IF(ROW()<=COUNTA(E:E), INDEX(E:E,ROW()), IF(ROW()>COUNTA(B:E), "", INDEX(B:B,ROW()-COUNTA(E:E)))))} | J3: {=IF(IF(ROW()<=COUNTA(F:F), INDEX(F:F,ROW()), IF(ROW()>COUNTA(C:F), "", INDEX(C:C,ROW()-COUNTA(F:F))))=0, "", IF(ROW()<=COUNTA(F:F), INDEX(F:F,ROW()), IF(ROW()>COUNTA(C:F), "", INDEX(C:C,ROW()-COUNTA(F:F)))))}
A4: 0 | B4: 0 | C4: =Credit!F5 -> 0 | D4: 0 | E4: 0 | F4: =Payment!F5 -> 0 | H4: {=IF(IF(ROW()<=COUNTA(D:D), INDEX(D:D,ROW()), IF(ROW()>COUNTA(A:D), "", INDEX(A:A,ROW()-COUNTA(D:D))))=0, "", IF(ROW()<=COUNTA(D:D), INDEX(D:D,ROW()), IF(ROW()>COUNTA(A:D), "", INDEX(A:A,ROW()-COUNTA(D:D)))))} | I4: {=IF(IF(ROW()<=COUNTA(E:E), INDEX(E:E,ROW()), IF(ROW()>COUNTA(B:E), "", INDEX(B:B,ROW()-COUNTA(E:E))))=0, "", IF(ROW()<=COUNTA(E:E), INDEX(E:E,ROW()), IF(ROW()>COUNTA(B:E), "", INDEX(B:B,ROW()-COUNTA(E:E)))))} | J4: {=IF(IF(ROW()<=COUNTA(F:F), INDEX(F:F,ROW()), IF(ROW()>COUNTA(C:F), "", INDEX(C:C,ROW()-COUNTA(F:F))))=0, "", IF(ROW()<=COUNTA(F:F), INDEX(F:F,ROW()), IF(ROW()>COUNTA(C:F), "", INDEX(C:C,ROW()-COUNTA(F:F)))))}
A5: 0 | B5: 0 | C5: =Credit!F6 -> 0 | D5: 0 | E5: 0 | F5: =Payment!F6 -> 0 | H5: {=IF(IF(ROW()<=COUNTA(D:D), INDEX(D:D,ROW()), IF(ROW()>COUNTA(A:D), "", INDEX(A:A,ROW()-COUNTA(D:D))))=0, "", IF(ROW()<=COUNTA(D:D), INDEX(D:D,ROW()), IF(ROW()>COUNTA(A:D), "", INDEX(A:A,ROW()-COUNTA(D:D)))))} | I5: {=IF(IF(ROW()<=COUNTA(E:E), INDEX(E:E,ROW()), IF(ROW()>COUNTA(B:E), "", INDEX(B:B,ROW()-COUNTA(E:E))))=0, "", IF(ROW()<=COUNTA(E:E), INDEX(E:E,ROW()), IF(ROW()>COUNTA(B:E), "", INDEX(B:B,ROW()-COUNTA(E:E)))))} | J5: {=IF(IF(ROW()<=COUNTA(F:F), INDEX(F:F,ROW()), IF(ROW()>COUNTA(C:F), "", INDEX(C:C,ROW()-COUNTA(F:F))))=0, "", IF(ROW()<=COUNTA(F:F), INDEX(F:F,ROW()), IF(ROW()>COUNTA(C:F), "", INDEX(C:C,ROW()-COUNTA(F:F)))))} | K5: Total Payments Less Credits | L5: =SUM(I:I) -> 0
A6: 0 | B6: 0 | C6: =Credit!F7 -> 0 | D6: 0 | E6: 0 | F6: =Payment!F7 -> 0 | H6: {=IF(IF(ROW()<=COUNTA(D:D), INDEX(D:D,ROW()), IF(ROW()>COUNTA(A:D), "", INDEX(A:A,ROW()-COUNTA(D:D))))=0, "", IF(ROW()<=COUNTA(D:D), INDEX(D:D,ROW()), IF(ROW()>COUNTA(A:D), "", INDEX(A:A,ROW()-COUNTA(D:D)))))} | I6: {=IF(IF(ROW()<=COUNTA(E:E), INDEX(E:E,ROW()), IF(ROW()>COUNTA(B:E), "", INDEX(B:B,ROW()-COUNTA(E:E))))=0, "", IF(ROW()<=COUNTA(E:E), INDEX(E:E,ROW()), IF(ROW()>COUNTA(B:E), "", INDEX(B:B,ROW()-COUNTA(E:E)))))} | J6: {=IF(IF(ROW()<=COUNTA(F:F), INDEX(F:F,ROW()), IF(ROW()>COUNTA(C:F), "", INDEX(C:C,ROW()-COUNTA(F:F))))=0, "", IF(ROW()<=COUNTA(F:F), INDEX(F:F,ROW()), IF(ROW()>COUNTA(C:F), "", INDEX(C:C,ROW()-COUNTA(F:F)))))} | K6: Total Payments | L6: =SUM(E:E) -> 0
A7: 0 | B7: 0 | C7: =Credit!F8 -> 0 | D7: 0 | E7: 0 | F7: =Payment!F8 -> 0 | H7: {=IF(IF(ROW()<=COUNTA(D:D), INDEX(D:D,ROW()), IF(ROW()>COUNTA(A:D), "", INDEX(A:A,ROW()-COUNTA(D:D))))=0, "", IF(ROW()<=COUNTA(D:D), INDEX(D:D,ROW()), IF(ROW()>COUNTA(A:D), "", INDEX(A:A,ROW()-COUNTA(D:D)))))} | I7: {=IF(IF(ROW()<=COUNTA(E:E), INDEX(E:E,ROW()), IF(ROW()>COUNTA(B:E), "", INDEX(B:B,ROW()-COUNTA(E:E))))=0, "", IF(ROW()<=COUNTA(E:E), INDEX(E:E,ROW()), IF(ROW()>COUNTA(B:E), "", INDEX(B:B,ROW()-COUNTA(E:E)))))} | J7: {=IF(IF(ROW()<=COUNTA(F:F), INDEX(F:F,ROW()), IF(ROW()>COUNTA(C:F), "", INDEX(C:C,ROW()-COUNTA(F:F))))=0, "", IF(ROW()<=COUNTA(F:F), INDEX(F:F,ROW()), IF(ROW()>COUNTA(C:F), "", INDEX(C:C,ROW()-COUNTA(F:F)))))} | K7: Total Credits | L7: =SUM(B:B) -> 0
A8: 0 | B8: 0 | C8: =Credit!F9 -> 0 | D8: 0 | E8: 0 | F8: =Payment!F9 -> 0 | H8: {=IF(IF(ROW()<=COUNTA(D:D), INDEX(D:D,ROW()), IF(ROW()>COUNTA(A:D), "", INDEX(A:A,ROW()-COUNTA(D:D))))=0, "", IF(ROW()<=COUNTA(D:D), INDEX(D:D,ROW()), IF(ROW()>COUNTA(A:D), "", INDEX(A:A,ROW()-COUNTA(D:D)))))} | I8: {=IF(IF(ROW()<=COUNTA(E:E), INDEX(E:E,ROW()), IF(ROW()>COUNTA(B:E), "", INDEX(B:B,ROW()-COUNTA(E:E))))=0, "", IF(ROW()<=COUNTA(E:E), INDEX(E:E,ROW()), IF(ROW()>COUNTA(B:E), "", INDEX(B:B,ROW()-COUNTA(E:E)))))} | J8: {=IF(IF(ROW()<=COUNTA(F:F), INDEX(F:F,ROW()), IF(ROW()>COUNTA(C:F), "", INDEX(C:C,ROW()-COUNTA(F:F))))=0, "", IF(ROW()<=COUNTA(F:F), INDEX(F:F,ROW()), IF(ROW()>COUNTA(C:F), "", INDEX(C:C,ROW()-COUNTA(F:F)))))}
A9: 0 | B9: 0 | C9: =Credit!F10 -> 0 | D9: 0 | E9: 0 | F9: =Payment!F10 -> 0 | H9: {=IF(IF(ROW()<=COUNTA(D:D), INDEX(D:D,ROW()), IF(ROW()>COUNTA(A:D), "", INDEX(A:A,ROW()-COUNTA(D:D))))=0, "", IF(ROW()<=COUNTA(D:D), INDEX(D:D,ROW()), IF(ROW()>COUNTA(A:D), "", INDEX(A:A,ROW()-COUNTA(D:D)))))} | I9: {=IF(IF(ROW()<=COUNTA(E:E), INDEX(E:E,ROW()), IF(ROW()>COUNTA(B:E), "", INDEX(B:B,ROW()-COUNTA(E:E))))=0, "", IF(ROW()<=COUNTA(E:E), INDEX(E:E,ROW()), IF(ROW()>COUNTA(B:E), "", INDEX(B:B,ROW()-COUNTA(E:E)))))} | J9: {=IF(IF(ROW()<=COUNTA(F:F), INDEX(F:F,ROW()), IF(ROW()>COUNTA(C:F), "", INDEX(C:C,ROW()-COUNTA(F:F))))=0, "", IF(ROW()<=COUNTA(F:F), INDEX(F:F,ROW()), IF(ROW()>COUNTA(C:F), "", INDEX(C:C,ROW()-COUNTA(F:F)))))}
A10: 0 | B10: 0 | C10: =Credit!F11 -> 0 | D10: 0 | E10: 0 | F10: =Payment!F11 -> 0 | H10: {=IF(IF(ROW()<=COUNTA(D:D), INDEX(D:D,ROW()), IF(ROW()>COUNTA(A:D), "", INDEX(A:A,ROW()-COUNTA(D:D))))=0, "", IF(ROW()<=COUNTA(D:D), INDEX(D:D,ROW()), IF(ROW()>COUNTA(A:D), "", INDEX(A:A,ROW()-COUNTA(D:D)))))} | I10: {=IF(IF(ROW()<=COUNTA(E:E), INDEX(E:E,ROW()), IF(ROW()>COUNTA(B:E), "", INDEX(B:B,ROW()-COUNTA(E:E))))=0, "", IF(ROW()<=COUNTA(E:E), INDEX(E:E,ROW()), IF(ROW()>COUNTA(B:E), "", INDEX(B:B,ROW()-COUNTA(E:E)))))} | J10: {=IF(IF(ROW()<=COUNTA(F:F), INDEX(F:F,ROW()), IF(ROW()>COUNTA(C:F), "", INDEX(C:C,ROW()-COUNTA(F:F))))=0, "", IF(ROW()<=COUNTA(F:F), INDEX(F:F,ROW()), IF(ROW()>COUNTA(C:F), "", INDEX(C:C,ROW()-COUNTA(F:F)))))}
A11: 0 | B11: 0 | C11: =Credit!F12 -> 0 | D11: 0 | E11: 0 | F11: =Payment!F12 -> 0 | H11: {=IF(IF(ROW()<=COUNTA(D:D), INDEX(D:D,ROW()), IF(ROW()>COUNTA(A:D), "", INDEX(A:A,ROW()-COUNTA(D:D))))=0, "", IF(ROW()<=COUNTA(D:D), INDEX(D:D,ROW()), IF(ROW()>COUNTA(A:D), "", INDEX(A:A,ROW()-COUNTA(D:D)))))} | I11: {=IF(IF(ROW()<=COUNTA(E:E), INDEX(E:E,ROW()), IF(ROW()>COUNTA(B:E), "", INDEX(B:B,ROW()-COUNTA(E:E))))=0, "", IF(ROW()<=COUNTA(E:E), INDEX(E:E,ROW()), IF(ROW()>COUNTA(B:E), "", INDEX(B:B,ROW()-COUNTA(E:E)))))} | J11: {=IF(IF(ROW()<=COUNTA(F:F), INDEX(F:F,ROW()), IF(ROW()>COUNTA(C:F), "", INDEX(C:C,ROW()-COUNTA(F:F))))=0, "", IF(ROW()<=COUNTA(F:F), INDEX(F:F,ROW()), IF(ROW()>COUNTA(C:F), "", INDEX(C:C,ROW()-COUNTA(F:F)))))}
A12: 0 | B12: 0 | C12: =Credit!F13 -> 0 | D12: 0 | E12: 0 | F12: =Payment!F13 -> 0 | H12: {=IF(IF(ROW()<=COUNTA(D:D), INDEX(D:D,ROW()), IF(ROW()>COUNTA(A:D), "", INDEX(A:A,ROW()-COUNTA(D:D))))=0, "", IF(ROW()<=COUNTA(D:D), INDEX(D:D,ROW()), IF(ROW()>COUNTA(A:D), "", INDEX(A:A,ROW()-COUNTA(D:D)))))} | I12: {=IF(IF(ROW()<=COUNTA(E:E), INDEX(E:E,ROW()), IF(ROW()>COUNTA(B:E), "", INDEX(B:B,ROW()-COUNTA(E:E))))=0, "", IF(ROW()<=COUNTA(E:E), INDEX(E:E,ROW()), IF(ROW()>COUNTA(B:E), "", INDEX(B:B,ROW()-COUNTA(E:E)))))} | J12: {=IF(IF(ROW()<=COUNTA(F:F), INDEX(F:F,ROW()), IF(ROW()>COUNTA(C:F), "", INDEX(C:C,ROW()-COUNTA(F:F))))=0, "", IF(ROW()<=COUNTA(F:F), INDEX(F:F,ROW()), IF(ROW()>COUNTA(C:F), "", INDEX(C:C,ROW()-COUNTA(F:F)))))}
A13: 0 | B13: 0 | C13: =Credit!F14 -> 0 | D13: 0 | E13: 0 | F13: =Payment!F14 -> 0 | H13: {=IF(IF(ROW()<=COUNTA(D:D), INDEX(D:D,ROW()), IF(ROW()>COUNTA(A:D), "", INDEX(A:A,ROW()-COUNTA(D:D))))=0, "", IF(ROW()<=COUNTA(D:D), INDEX(D:D,ROW()), IF(ROW()>COUNTA(A:D), "", INDEX(A:A,ROW()-COUNTA(D:D)))))} | I13: {=IF(IF(ROW()<=COUNTA(E:E), INDEX(E:E,ROW()), IF(ROW()>COUNTA(B:E), "", INDEX(B:B,ROW()-COUNTA(E:E))))=0, "", IF(ROW()<=COUNTA(E:E), INDEX(E:E,ROW()), IF(ROW()>COUNTA(B:E), "", INDEX(B:B,ROW()-COUNTA(E:E)))))} | J13: {=IF(IF(ROW()<=COUNTA(F:F), INDEX(F:F,ROW()), IF(ROW()>COUNTA(C:F), "", INDEX(C:C,ROW()-COUNTA(F:F))))=0, "", IF(ROW()<=COUNTA(F:F), INDEX(F:F,ROW()), IF(ROW()>COUNTA(C:F), "", INDEX(C:C,ROW()-COUNTA(F:F)))))}
A14: 0 | B14: 0 | C14: =Credit!F15 -> 0 | D14: 0 | E14: 0 | F14: =Payment!F15 -> 0 | H14: {=IF(IF(ROW()<=COUNTA(D:D), INDEX(D:D,ROW()), IF(ROW()>COUNTA(A:D), "", INDEX(A:A,ROW()-COUNTA(D:D))))=0, "", IF(ROW()<=COUNTA(D:D), INDEX(D:D,ROW()), IF(ROW()>COUNTA(A:D), "", INDEX(A:A,ROW()-COUNTA(D:D)))))} | I14: {=IF(IF(ROW()<=COUNTA(E:E), INDEX(E:E,ROW()), IF(ROW()>COUNTA(B:E), "", INDEX(B:B,ROW()-COUNTA(E:E))))=0, "", IF(ROW()<=COUNTA(E:E), INDEX(E:E,ROW()), IF(ROW()>COUNTA(B:E), "", INDEX(B:B,ROW()-COUNTA(E:E)))))} | J14: {=IF(IF(ROW()<=COUNTA(F:F), INDEX(F:F,ROW()), IF(ROW()>COUNTA(C:F), "", INDEX(C:C,ROW()-COUNTA(F:F))))=0, "", IF(ROW()<=COUNTA(F:F), INDEX(F:F,ROW()), IF(ROW()>COUNTA(C:F), "", INDEX(C:C,ROW()-COUNTA(F:F)))))}
A15: 0 | B15: 0 | C15: =Credit!F16 -> 0 | D15: 0 | E15: 0 | F15: =Payment!F16 -> 0 | H15: {=IF(IF(ROW()<=COUNTA(D:D), INDEX(D:D,ROW()), IF(ROW()>COUNTA(A:D), "", INDEX(A:A,ROW()-COUNTA(D:D))))=0, "", IF(ROW()<=COUNTA(D:D), INDEX(D:D,ROW()), IF(ROW()>COUNTA(A:D), "", INDEX(A:A,ROW()-COUNTA(D:D)))))} | I15: {=IF(IF(ROW()<=COUNTA(E:E), INDEX(E:E,ROW()), IF(ROW()>COUNTA(B:E), "", INDEX(B:B,ROW()-COUNTA(E:E))))=0, "", IF(ROW()<=COUNTA(E:E), INDEX(E:E,ROW()), IF(ROW()>COUNTA(B:E), "", INDEX(B:B,ROW()-COUNTA(E:E)))))} | J15: {=IF(IF(ROW()<=COUNTA(F:F), INDEX(F:F,ROW()), IF(ROW()>COUNTA(C:F), "", INDEX(C:C,ROW()-COUNTA(F:F))))=0, "", IF(ROW()<=COUNTA(F:F), INDEX(F:F,ROW()), IF(ROW()>COUNTA(C:F), "", INDEX(C:C,ROW()-COUNTA(F:F)))))}
A16: 0 | B16: 0 | C16: =Credit!F17 -> 0 | D16: 0 | E16: 0 | F16: =Payment!F17 -> 0 | H16: {=IF(IF(ROW()<=COUNTA(D:D), INDEX(D:D,ROW()), IF(ROW()>COUNTA(A:D), "", INDEX(A:A,ROW()-COUNTA(D:D))))=0, "", IF(ROW()<=COUNTA(D:D), INDEX(D:D,ROW()), IF(ROW()>COUNTA(A:D), "", INDEX(A:A,ROW()-COUNTA(D:D)))))} | I16: {=IF(IF(ROW()<=COUNTA(E:E), INDEX(E:E,ROW()), IF(ROW()>COUNTA(B:E), "", INDEX(B:B,ROW()-COUNTA(E:E))))=0, "", IF(ROW()<=COUNTA(E:E), INDEX(E:E,ROW()), IF(ROW()>COUNTA(B:E), "", INDEX(B:B,ROW()-COUNTA(E:E)))))} | J16: {=IF(IF(ROW()<=COUNTA(F:F), INDEX(F:F,ROW()), IF(ROW()>COUNTA(C:F), "", INDEX(C:C,ROW()-COUNTA(F:F))))=0, "", IF(ROW()<=COUNTA(F:F), INDEX(F:F,ROW()), IF(ROW()>COUNTA(C:F), "", INDEX(C:C,ROW()-COUNTA(F:F)))))}
A17: 0 | B17: 0 | C17: =Credit!F18 -> 0 | D17: 0 | E17: 0 | F17: =Payment!F18 -> 0 | H17: {=IF(IF(ROW()<=COUNTA(D:D), INDEX(D:D,ROW()), IF(ROW()>COUNTA(A:D), "", INDEX(A:A,ROW()-COUNTA(D:D))))=0, "", IF(ROW()<=COUNTA(D:D), INDEX(D:D,ROW()), IF(ROW()>COUNTA(A:D), "", INDEX(A:A,ROW()-COUNTA(D:D)))))} | I17: {=IF(IF(ROW()<=COUNTA(E:E), INDEX(E:E,ROW()), IF(ROW()>COUNTA(B:E), "", INDEX(B:B,ROW()-COUNTA(E:E))))=0, "", IF(ROW()<=COUNTA(E:E), INDEX(E:E,ROW()), IF(ROW()>COUNTA(B:E), "", INDEX(B:B,ROW()-COUNTA(E:E)))))} | J17: {=IF(IF(ROW()<=COUNTA(F:F), INDEX(F:F,ROW()), IF(ROW()>COUNTA(C:F), "", INDEX(C:C,ROW()-COUNTA(F:F))))=0, "", IF(ROW()<=COUNTA(F:F), INDEX(F:F,ROW()), IF(ROW()>COUNTA(C:F), "", INDEX(C:C,ROW()-COUNTA(F:F)))))}
A18: 0 | B18: 0 | C18: =Credit!F19 -> 0 | D18: 0 | E18: 0 | F18: =Payment!F19 -> 0 | H18: {=IF(IF(ROW()<=COUNTA(D:D), INDEX(D:D,ROW()), IF(ROW()>COUNTA(A:D), "", INDEX(A:A,ROW()-COUNTA(D:D))))=0, "", IF(ROW()<=COUNTA(D:D), INDEX(D:D,ROW()), IF(ROW()>COUNTA(A:D), "", INDEX(A:A,ROW()-COUNTA(D:D)))))} | I18: {=IF(IF(ROW()<=COUNTA(E:E), INDEX(E:E,ROW()), IF(ROW()>COUNTA(B:E), "", INDEX(B:B,ROW()-COUNTA(E:E))))=0, "", IF(ROW()<=COUNTA(E:E), INDEX(E:E,ROW()), IF(ROW()>COUNTA(B:E), "", INDEX(B:B,ROW()-COUNTA(E:E)))))} | J18: {=IF(IF(ROW()<=COUNTA(F:F), INDEX(F:F,ROW()), IF(ROW()>COUNTA(C:F), "", INDEX(C:C,ROW()-COUNTA(F:F))))=0, "", IF(ROW()<=COUNTA(F:F), INDEX(F:F,ROW()), IF(ROW()>COUNTA(C:F), "", INDEX(C:C,ROW()-COUNTA(F:F)))))}
A19: 0 | B19: 0 | C19: =Credit!F20 -> 0 | D19: 0 | E19: 0 | F19: =Payment!F20 -> 0 | H19: {=IF(IF(ROW()<=COUNTA(D:D), INDEX(D:D,ROW()), IF(ROW()>COUNTA(A:D), "", INDEX(A:A,ROW()-COUNTA(D:D))))=0, "", IF(ROW()<=COUNTA(D:D), INDEX(D:D,ROW()), IF(ROW()>COUNTA(A:D), "", INDEX(A:A,ROW()-COUNTA(D:D)))))} | I19: {=IF(IF(ROW()<=COUNTA(E:E), INDEX(E:E,ROW()), IF(ROW()>COUNTA(B:E), "", INDEX(B:B,ROW()-COUNTA(E:E))))=0, "", IF(ROW()<=COUNTA(E:E), INDEX(E:E,ROW()), IF(ROW()>COUNTA(B:E), "", INDEX(B:B,ROW()-COUNTA(E:E)))))} | J19: {=IF(IF(ROW()<=COUNTA(F:F), INDEX(F:F,ROW()), IF(ROW()>COUNTA(C:F), "", INDEX(C:C,ROW()-COUNTA(F:F))))=0, "", IF(ROW()<=COUNTA(F:F), INDEX(F:F,ROW()), IF(ROW()>COUNTA(C:F), "", INDEX(C:C,ROW()-COUNTA(F:F)))))}
... A250: 0 | B250: 0 | C250: =Credit!F251 -> 0 | D250: 0 | E250: 0 | F250: =Payment!F251 -> 0 | H250: {=IF(IF(ROW()<=COUNTA(D:D), INDEX(D:D,ROW()), IF(ROW()>COUNTA(A:D), "", INDEX(A:A,ROW()-COUNTA(D:D))))=0, "", IF(ROW()<=COUNTA(D:D), INDEX(D:D,ROW()), IF(ROW()>COUNTA(A:D), "", INDEX(A:A,ROW()-COUNTA(D:D)))))} | I250: {=IF(IF(ROW()<=COUNTA(E:E), INDEX(E:E,ROW()), IF(ROW()>COUNTA(B:E), "", INDEX(B:B,ROW()-COUNTA(E:E))))=0, "", IF(ROW()<=COUNTA(E:E), INDEX(E:E,ROW()), IF(ROW()>COUNTA(B:E), "", INDEX(B:B,ROW()-COUNTA(E:E)))))} | J250: {=IF(IF(ROW()<=COUNTA(F:F), INDEX(F:F,ROW()), IF(ROW()>COUNTA(C:F), "", INDEX(C:C,ROW()-COUNTA(F:F))))=0, "", IF(ROW()<=COUNTA(F:F), INDEX(F:F,ROW()), IF(ROW()>COUNTA(C:F), "", INDEX(C:C,ROW()-COUNTA(F:F)))))}
A251: 0 | C251: =Credit!F252 -> 0 | D251: 0 | E251: 0 | F251: =Payment!F252 -> 0 | H251: {=IF(IF(ROW()<=COUNTA(D:D), INDEX(D:D,ROW()), IF(ROW()>COUNTA(A:D), "", INDEX(A:A,ROW()-COUNTA(D:D))))=0, "", IF(ROW()<=COUNTA(D:D), INDEX(D:D,ROW()), IF(ROW()>COUNTA(A:D), "", INDEX(A:A,ROW()-COUNTA(D:D)))))} | I251: {=IF(IF(ROW()<=COUNTA(E:E), INDEX(E:E,ROW()), IF(ROW()>COUNTA(B:E), "", INDEX(B:B,ROW()-COUNTA(E:E))))=0, "", IF(ROW()<=COUNTA(E:E), INDEX(E:E,ROW()), IF(ROW()>COUNTA(B:E), "", INDEX(B:B,ROW()-COUNTA(E:E)))))} | J251: {=IF(IF(ROW()<=COUNTA(F:F), INDEX(F:F,ROW()), IF(ROW()>COUNTA(C:F), "", INDEX(C:C,ROW()-COUNTA(F:F))))=0, "", IF(ROW()<=COUNTA(F:F), INDEX(F:F,ROW()), IF(ROW()>COUNTA(C:F), "", INDEX(C:C,ROW()-COUNTA(F:F)))))}
A252: 0 | C252: =Credit!F253 -> 0 | D252: 0 | E252: 0 | F252: =Payment!F253 -> 0 | H252: {=IF(IF(ROW()<=COUNTA(D:D), INDEX(D:D,ROW()), IF(ROW()>COUNTA(A:D), "", INDEX(A:A,ROW()-COUNTA(D:D))))=0, "", IF(ROW()<=COUNTA(D:D), INDEX(D:D,ROW()), IF(ROW()>COUNTA(A:D), "", INDEX(A:A,ROW()-COUNTA(D:D)))))} | I252: {=IF(IF(ROW()<=COUNTA(E:E), INDEX(E:E,ROW()), IF(ROW()>COUNTA(B:E), "", INDEX(B:B,ROW()-COUNTA(E:E))))=0, "", IF(ROW()<=COUNTA(E:E), INDEX(E:E,ROW()), IF(ROW()>COUNTA(B:E), "", INDEX(B:B,ROW()-COUNTA(E:E)))))} | J252: {=IF(IF(ROW()<=COUNTA(F:F), INDEX(F:F,ROW()), IF(ROW()>COUNTA(C:F), "", INDEX(C:C,ROW()-COUNTA(F:F))))=0, "", IF(ROW()<=COUNTA(F:F), INDEX(F:F,ROW()), IF(ROW()>COUNTA(C:F), "", INDEX(C:C,ROW()-COUNTA(F:F)))))}
A253: 0 | C253: =Credit!F254 -> 0 | D253: 0 | E253: 0 | F253: =Payment!F254 -> 0 | H253: {=IF(IF(ROW()<=COUNTA(D:D), INDEX(D:D,ROW()), IF(ROW()>COUNTA(A:D), "", INDEX(A:A,ROW()-COUNTA(D:D))))=0, "", IF(ROW()<=COUNTA(D:D), INDEX(D:D,ROW()), IF(ROW()>COUNTA(A:D), "", INDEX(A:A,ROW()-COUNTA(D:D)))))} | I253: {=IF(IF(ROW()<=COUNTA(E:E), INDEX(E:E,ROW()), IF(ROW()>COUNTA(B:E), "", INDEX(B:B,ROW()-COUNTA(E:E))))=0, "", IF(ROW()<=COUNTA(E:E), INDEX(E:E,ROW()), IF(ROW()>COUNTA(B:E), "", INDEX(B:B,ROW()-COUNTA(E:E)))))} | J253: {=IF(IF(ROW()<=COUNTA(F:F), INDEX(F:F,ROW()), IF(ROW()>COUNTA(C:F), "", INDEX(C:C,ROW()-COUNTA(F:F))))=0, "", IF(ROW()<=COUNTA(F:F), INDEX(F:F,ROW()), IF(ROW()>COUNTA(C:F), "", INDEX(C:C,ROW()-COUNTA(F:F)))))}
A254: 0 | C254: =Credit!F255 -> 0 | D254: 0 | E254: 0 | F254: =Payment!F255 -> 0 | H254: {=IF(IF(ROW()<=COUNTA(D:D), INDEX(D:D,ROW()), IF(ROW()>COUNTA(A:D), "", INDEX(A:A,ROW()-COUNTA(D:D))))=0, "", IF(ROW()<=COUNTA(D:D), INDEX(D:D,ROW()), IF(ROW()>COUNTA(A:D), "", INDEX(A:A,ROW()-COUNTA(D:D)))))} | I254: {=IF(IF(ROW()<=COUNTA(E:E), INDEX(E:E,ROW()), IF(ROW()>COUNTA(B:E), "", INDEX(B:B,ROW()-COUNTA(E:E))))=0, "", IF(ROW()<=COUNTA(E:E), INDEX(E:E,ROW()), IF(ROW()>COUNTA(B:E), "", INDEX(B:B,ROW()-COUNTA(E:E)))))} | J254: {=IF(IF(ROW()<=COUNTA(F:F), INDEX(F:F,ROW()), IF(ROW()>COUNTA(C:F), "", INDEX(C:C,ROW()-COUNTA(F:F))))=0, "", IF(ROW()<=COUNTA(F:F), INDEX(F:F,ROW()), IF(ROW()>COUNTA(C:F), "", INDEX(C:C,ROW()-COUNTA(F:F)))))}
A255: 0 | C255: =Credit!F256 -> 0 | D255: 0 | E255: 0 | F255: =Payment!F256 -> 0 | H255: {=IF(IF(ROW()<=COUNTA(D:D), INDEX(D:D,ROW()), IF(ROW()>COUNTA(A:D), "", INDEX(A:A,ROW()-COUNTA(D:D))))=0, "", IF(ROW()<=COUNTA(D:D), INDEX(D:D,ROW()), IF(ROW()>COUNTA(A:D), "", INDEX(A:A,ROW()-COUNTA(D:D)))))} | I255: {=IF(IF(ROW()<=COUNTA(E:E), INDEX(E:E,ROW()), IF(ROW()>COUNTA(B:E), "", INDEX(B:B,ROW()-COUNTA(E:E))))=0, "", IF(ROW()<=COUNTA(E:E), INDEX(E:E,ROW()), IF(ROW()>COUNTA(B:E), "", INDEX(B:B,ROW()-COUNTA(E:E)))))} | J255: {=IF(IF(ROW()<=COUNTA(F:F), INDEX(F:F,ROW()), IF(ROW()>COUNTA(C:F), "", INDEX(C:C,ROW()-COUNTA(F:F))))=0, "", IF(ROW()<=COUNTA(F:F), INDEX(F:F,ROW()), IF(ROW()>COUNTA(C:F), "", INDEX(C:C,ROW()-COUNTA(F:F)))))}
A256: 0 | C256: =Credit!F257 -> 0 | D256: 0 | E256: 0 | F256: =Payment!F257 -> 0 | H256: {=IF(IF(ROW()<=COUNTA(D:D), INDEX(D:D,ROW()), IF(ROW()>COUNTA(A:D), "", INDEX(A:A,ROW()-COUNTA(D:D))))=0, "", IF(ROW()<=COUNTA(D:D), INDEX(D:D,ROW()), IF(ROW()>COUNTA(A:D), "", INDEX(A:A,ROW()-COUNTA(D:D)))))} | I256: {=IF(IF(ROW()<=COUNTA(E:E), INDEX(E:E,ROW()), IF(ROW()>COUNTA(B:E), "", INDEX(B:B,ROW()-COUNTA(E:E))))=0, "", IF(ROW()<=COUNTA(E:E), INDEX(E:E,ROW()), IF(ROW()>COUNTA(B:E), "", INDEX(B:B,ROW()-COUNTA(E:E)))))} | J256: {=IF(IF(ROW()<=COUNTA(F:F), INDEX(F:F,ROW()), IF(ROW()>COUNTA(C:F), "", INDEX(C:C,ROW()-COUNTA(F:F))))=0, "", IF(ROW()<=COUNTA(F:F), INDEX(F:F,ROW()), IF(ROW()>COUNTA(C:F), "", INDEX(C:C,ROW()-COUNTA(F:F)))))}
A257: 0 | C257: =Credit!F258 -> 0 | D257: 0 | E257: 0 | F257: =Payment!F258 -> 0 | H257: {=IF(IF(ROW()<=COUNTA(D:D), INDEX(D:D,ROW()), IF(ROW()>COUNTA(A:D), "", INDEX(A:A,ROW()-COUNTA(D:D))))=0, "", IF(ROW()<=COUNTA(D:D), INDEX(D:D,ROW()), IF(ROW()>COUNTA(A:D), "", INDEX(A:A,ROW()-COUNTA(D:D)))))} | I257: {=IF(IF(ROW()<=COUNTA(E:E), INDEX(E:E,ROW()), IF(ROW()>COUNTA(B:E), "", INDEX(B:B,ROW()-COUNTA(E:E))))=0, "", IF(ROW()<=COUNTA(E:E), INDEX(E:E,ROW()), IF(ROW()>COUNTA(B:E), "", INDEX(B:B,ROW()-COUNTA(E:E)))))} | J257: {=IF(IF(ROW()<=COUNTA(F:F), INDEX(F:F,ROW()), IF(ROW()>COUNTA(C:F), "", INDEX(C:C,ROW()-COUNTA(F:F))))=0, "", IF(ROW()<=COUNTA(F:F), INDEX(F:F,ROW()), IF(ROW()>COUNTA(C:F), "", INDEX(C:C,ROW()-COUNTA(F:F)))))}
A258: 0 | C258: =Credit!F259 -> 0 | D258: 0 | E258: 0 | F258: =Payment!F259 -> 0 | H258: {=IF(IF(ROW()<=COUNTA(D:D), INDEX(D:D,ROW()), IF(ROW()>COUNTA(A:D), "", INDEX(A:A,ROW()-COUNTA(D:D))))=0, "", IF(ROW()<=COUNTA(D:D), INDEX(D:D,ROW()), IF(ROW()>COUNTA(A:D), "", INDEX(A:A,ROW()-COUNTA(D:D)))))} | I258: {=IF(IF(ROW()<=COUNTA(E:E), INDEX(E:E,ROW()), IF(ROW()>COUNTA(B:E), "", INDEX(B:B,ROW()-COUNTA(E:E))))=0, "", IF(ROW()<=COUNTA(E:E), INDEX(E:E,ROW()), IF(ROW()>COUNTA(B:E), "", INDEX(B:B,ROW()-COUNTA(E:E)))))} | J258: {=IF(IF(ROW()<=COUNTA(F:F), INDEX(F:F,ROW()), IF(ROW()>COUNTA(C:F), "", INDEX(C:C,ROW()-COUNTA(F:F))))=0, "", IF(ROW()<=COUNTA(F:F), INDEX(F:F,ROW()), IF(ROW()>COUNTA(C:F), "", INDEX(C:C,ROW()-COUNTA(F:F)))))}
A259: 0 | C259: =Credit!F260 -> 0 | D259: 0 | E259: 0 | F259: =Payment!F260 -> 0 | H259: {=IF(IF(ROW()<=COUNTA(D:D), INDEX(D:D,ROW()), IF(ROW()>COUNTA(A:D), "", INDEX(A:A,ROW()-COUNTA(D:D))))=0, "", IF(ROW()<=COUNTA(D:D), INDEX(D:D,ROW()), IF(ROW()>COUNTA(A:D), "", INDEX(A:A,ROW()-COUNTA(D:D)))))} | I259: {=IF(IF(ROW()<=COUNTA(E:E), INDEX(E:E,ROW()), IF(ROW()>COUNTA(B:E), "", INDEX(B:B,ROW()-COUNTA(E:E))))=0, "", IF(ROW()<=COUNTA(E:E), INDEX(E:E,ROW()), IF(ROW()>COUNTA(B:E), "", INDEX(B:B,ROW()-COUNTA(E:E)))))} | J259: {=IF(IF(ROW()<=COUNTA(F:F), INDEX(F:F,ROW()), IF(ROW()>COUNTA(C:F), "", INDEX(C:C,ROW()-COUNTA(F:F))))=0, "", IF(ROW()<=COUNTA(F:F), INDEX(F:F,ROW()), IF(ROW()>COUNTA(C:F), "", INDEX(C:C,ROW()-COUNTA(F:F)))))}
A260: 0 | C260: =Credit!F261 -> 0 | D260: 0 | E260: 0 | F260: =Payment!F261 -> 0 | H260: {=IF(IF(ROW()<=COUNTA(D:D), INDEX(D:D,ROW()), IF(ROW()>COUNTA(A:D), "", INDEX(A:A,ROW()-COUNTA(D:D))))=0, "", IF(ROW()<=COUNTA(D:D), INDEX(D:D,ROW()), IF(ROW()>COUNTA(A:D), "", INDEX(A:A,ROW()-COUNTA(D:D)))))} | I260: {=IF(IF(ROW()<=COUNTA(E:E), INDEX(E:E,ROW()), IF(ROW()>COUNTA(B:E), "", INDEX(B:B,ROW()-COUNTA(E:E))))=0, "", IF(ROW()<=COUNTA(E:E), INDEX(E:E,ROW()), IF(ROW()>COUNTA(B:E), "", INDEX(B:B,ROW()-COUNTA(E:E)))))} | J260: {=IF(IF(ROW()<=COUNTA(F:F), INDEX(F:F,ROW()), IF(ROW()>COUNTA(C:F), "", INDEX(C:C,ROW()-COUNTA(F:F))))=0, "", IF(ROW()<=COUNTA(F:F), INDEX(F:F,ROW()), IF(ROW()>COUNTA(C:F), "", INDEX(C:C,ROW()-COUNTA(F:F)))))}
A261: 0 | C261: =Credit!F262 -> 0 | D261: 0 | E261: 0 | F261: =Payment!F262 -> 0 | H261: {=IF(IF(ROW()<=COUNTA(D:D), INDEX(D:D,ROW()), IF(ROW()>COUNTA(A:D), "", INDEX(A:A,ROW()-COUNTA(D:D))))=0, "", IF(ROW()<=COUNTA(D:D), INDEX(D:D,ROW()), IF(ROW()>COUNTA(A:D), "", INDEX(A:A,ROW()-COUNTA(D:D)))))} | I261: {=IF(IF(ROW()<=COUNTA(E:E), INDEX(E:E,ROW()), IF(ROW()>COUNTA(B:E), "", INDEX(B:B,ROW()-COUNTA(E:E))))=0, "", IF(ROW()<=COUNTA(E:E), INDEX(E:E,ROW()), IF(ROW()>COUNTA(B:E), "", INDEX(B:B,ROW()-COUNTA(E:E)))))} | J261: {=IF(IF(ROW()<=COUNTA(F:F), INDEX(F:F,ROW()), IF(ROW()>COUNTA(C:F), "", INDEX(C:C,ROW()-COUNTA(F:F))))=0, "", IF(ROW()<=COUNTA(F:F), INDEX(F:F,ROW()), IF(ROW()>COUNTA(C:F), "", INDEX(C:C,ROW()-COUNTA(F:F)))))}
A262: 0 | C262: =Credit!F263 -> 0 | D262: 0 | E262: 0 | F262: =Payment!F263 -> 0 | H262: {=IF(IF(ROW()<=COUNTA(D:D), INDEX(D:D,ROW()), IF(ROW()>COUNTA(A:D), "", INDEX(A:A,ROW()-COUNTA(D:D))))=0, "", IF(ROW()<=COUNTA(D:D), INDEX(D:D,ROW()), IF(ROW()>COUNTA(A:D), "", INDEX(A:A,ROW()-COUNTA(D:D)))))} | I262: {=IF(IF(ROW()<=COUNTA(E:E), INDEX(E:E,ROW()), IF(ROW()>COUNTA(B:E), "", INDEX(B:B,ROW()-COUNTA(E:E))))=0, "", IF(ROW()<=COUNTA(E:E), INDEX(E:E,ROW()), IF(ROW()>COUNTA(B:E), "", INDEX(B:B,ROW()-COUNTA(E:E)))))} | J262: {=IF(IF(ROW()<=COUNTA(F:F), INDEX(F:F,ROW()), IF(ROW()>COUNTA(C:F), "", INDEX(C:C,ROW()-COUNTA(F:F))))=0, "", IF(ROW()<=COUNTA(F:F), INDEX(F:F,ROW()), IF(ROW()>COUNTA(C:F), "", INDEX(C:C,ROW()-COUNTA(F:F)))))}
... A349: 0 | C349: =Credit!F350 -> 0 | D349: 0 | E349: 0 | F349: =Payment!F350 -> 0 | H349: {=IF(IF(ROW()<=COUNTA(D:D), INDEX(D:D,ROW()), IF(ROW()>COUNTA(A:D), "", INDEX(A:A,ROW()-COUNTA(D:D))))=0, "", IF(ROW()<=COUNTA(D:D), INDEX(D:D,ROW()), IF(ROW()>COUNTA(A:D), "", INDEX(A:A,ROW()-COUNTA(D:D)))))} | I349: {=IF(IF(ROW()<=COUNTA(E:E), INDEX(E:E,ROW()), IF(ROW()>COUNTA(B:E), "", INDEX(B:B,ROW()-COUNTA(E:E))))=0, "", IF(ROW()<=COUNTA(E:E), INDEX(E:E,ROW()), IF(ROW()>COUNTA(B:E), "", INDEX(B:B,ROW()-COUNTA(E:E)))))} | J349: {=IF(IF(ROW()<=COUNTA(F:F), INDEX(F:F,ROW()), IF(ROW()>COUNTA(C:F), "", INDEX(C:C,ROW()-COUNTA(F:F))))=0, "", IF(ROW()<=COUNTA(F:F), INDEX(F:F,ROW()), IF(ROW()>COUNTA(C:F), "", INDEX(C:C,ROW()-COUNTA(F:F)))))}
C350: =Credit!F351 -> 0 | D350: 0 | E350: 0 | F350: =Payment!F351 -> 0 | H350: {=IF(IF(ROW()<=COUNTA(D:D), INDEX(D:D,ROW()), IF(ROW()>COUNTA(A:D), "", INDEX(A:A,ROW()-COUNTA(D:D))))=0, "", IF(ROW()<=COUNTA(D:D), INDEX(D:D,ROW()), IF(ROW()>COUNTA(A:D), "", INDEX(A:A,ROW()-COUNTA(D:D)))))} | I350: {=IF(IF(ROW()<=COUNTA(E:E), INDEX(E:E,ROW()), IF(ROW()>COUNTA(B:E), "", INDEX(B:B,ROW()-COUNTA(E:E))))=0, "", IF(ROW()<=COUNTA(E:E), INDEX(E:E,ROW()), IF(ROW()>COUNTA(B:E), "", INDEX(B:B,ROW()-COUNTA(E:E)))))} | J350: {=IF(IF(ROW()<=COUNTA(F:F), INDEX(F:F,ROW()), IF(ROW()>COUNTA(C:F), "", INDEX(C:C,ROW()-COUNTA(F:F))))=0, "", IF(ROW()<=COUNTA(F:F), INDEX(F:F,ROW()), IF(ROW()>COUNTA(C:F), "", INDEX(C:C,ROW()-COUNTA(F:F)))))}
C351: =Credit!F352 -> 0 | D351: 0 | E351: 0 | F351: =Payment!F352 -> 0 | H351: {=IF(IF(ROW()<=COUNTA(D:D), INDEX(D:D,ROW()), IF(ROW()>COUNTA(A:D), "", INDEX(A:A,ROW()-COUNTA(D:D))))=0, "", IF(ROW()<=COUNTA(D:D), INDEX(D:D,ROW()), IF(ROW()>COUNTA(A:D), "", INDEX(A:A,ROW()-COUNTA(D:D)))))} | I351: {=IF(IF(ROW()<=COUNTA(E:E), INDEX(E:E,ROW()), IF(ROW()>COUNTA(B:E), "", INDEX(B:B,ROW()-COUNTA(E:E))))=0, "", IF(ROW()<=COUNTA(E:E), INDEX(E:E,ROW()), IF(ROW()>COUNTA(B:E), "", INDEX(B:B,ROW()-COUNTA(E:E)))))} | J351: {=IF(IF(ROW()<=COUNTA(F:F), INDEX(F:F,ROW()), IF(ROW()>COUNTA(C:F), "", INDEX(C:C,ROW()-COUNTA(F:F))))=0, "", IF(ROW()<=COUNTA(F:F), INDEX(F:F,ROW()), IF(ROW()>COUNTA(C:F), "", INDEX(C:C,ROW()-COUNTA(F:F)))))}
C352: =Credit!F353 -> 0 | D352: 0 | E352: 0 | F352: =Payment!F353 -> 0 | H352: {=IF(IF(ROW()<=COUNTA(D:D), INDEX(D:D,ROW()), IF(ROW()>COUNTA(A:D), "", INDEX(A:A,ROW()-COUNTA(D:D))))=0, "", IF(ROW()<=COUNTA(D:D), INDEX(D:D,ROW()), IF(ROW()>COUNTA(A:D), "", INDEX(A:A,ROW()-COUNTA(D:D)))))} | I352: {=IF(IF(ROW()<=COUNTA(E:E), INDEX(E:E,ROW()), IF(ROW()>COUNTA(B:E), "", INDEX(B:B,ROW()-COUNTA(E:E))))=0, "", IF(ROW()<=COUNTA(E:E), INDEX(E:E,ROW()), IF(ROW()>COUNTA(B:E), "", INDEX(B:B,ROW()-COUNTA(E:E)))))} | J352: {=IF(IF(ROW()<=COUNTA(F:F), INDEX(F:F,ROW()), IF(ROW()>COUNTA(C:F), "", INDEX(C:C,ROW()-COUNTA(F:F))))=0, "", IF(ROW()<=COUNTA(F:F), INDEX(F:F,ROW()), IF(ROW()>COUNTA(C:F), "", INDEX(C:C,ROW()-COUNTA(F:F)))))}
C353: =Credit!F354 -> 0 | D353: 0 | E353: 0 | F353: =Payment!F354 -> 0 | H353: {=IF(IF(ROW()<=COUNTA(D:D), INDEX(D:D,ROW()), IF(ROW()>COUNTA(A:D), "", INDEX(A:A,ROW()-COUNTA(D:D))))=0, "", IF(ROW()<=COUNTA(D:D), INDEX(D:D,ROW()), IF(ROW()>COUNTA(A:D), "", INDEX(A:A,ROW()-COUNTA(D:D)))))} | I353: {=IF(IF(ROW()<=COUNTA(E:E), INDEX(E:E,ROW()), IF(ROW()>COUNTA(B:E), "", INDEX(B:B,ROW()-COUNTA(E:E))))=0, "", IF(ROW()<=COUNTA(E:E), INDEX(E:E,ROW()), IF(ROW()>COUNTA(B:E), "", INDEX(B:B,ROW()-COUNTA(E:E)))))} | J353: {=IF(IF(ROW()<=COUNTA(F:F), INDEX(F:F,ROW()), IF(ROW()>COUNTA(C:F), "", INDEX(C:C,ROW()-COUNTA(F:F))))=0, "", IF(ROW()<=COUNTA(F:F), INDEX(F:F,ROW()), IF(ROW()>COUNTA(C:F), "", INDEX(C:C,ROW()-COUNTA(F:F)))))}
C354: =Credit!F355 -> 0 | D354: 0 | E354: 0 | F354: =Payment!F355 -> 0 | H354: {=IF(IF(ROW()<=COUNTA(D:D), INDEX(D:D,ROW()), IF(ROW()>COUNTA(A:D), "", INDEX(A:A,ROW()-COUNTA(D:D))))=0, "", IF(ROW()<=COUNTA(D:D), INDEX(D:D,ROW()), IF(ROW()>COUNTA(A:D), "", INDEX(A:A,ROW()-COUNTA(D:D)))))} | I354: {=IF(IF(ROW()<=COUNTA(E:E), INDEX(E:E,ROW()), IF(ROW()>COUNTA(B:E), "", INDEX(B:B,ROW()-COUNTA(E:E))))=0, "", IF(ROW()<=COUNTA(E:E), INDEX(E:E,ROW()), IF(ROW()>COUNTA(B:E), "", INDEX(B:B,ROW()-COUNTA(E:E)))))} | J354: {=IF(IF(ROW()<=COUNTA(F:F), INDEX(F:F,ROW()), IF(ROW()>COUNTA(C:F), "", INDEX(C:C,ROW()-COUNTA(F:F))))=0, "", IF(ROW()<=COUNTA(F:F), INDEX(F:F,ROW()), IF(ROW()>COUNTA(C:F), "", INDEX(C:C,ROW()-COUNTA(F:F)))))}
C355: =Credit!F356 -> 0 | D355: 0 | E355: 0 | F355: =Payment!F356 -> 0 | H355: {=IF(IF(ROW()<=COUNTA(D:D), INDEX(D:D,ROW()), IF(ROW()>COUNTA(A:D), "", INDEX(A:A,ROW()-COUNTA(D:D))))=0, "", IF(ROW()<=COUNTA(D:D), INDEX(D:D,ROW()), IF(ROW()>COUNTA(A:D), "", INDEX(A:A,ROW()-COUNTA(D:D)))))} | I355: {=IF(IF(ROW()<=COUNTA(E:E), INDEX(E:E,ROW()), IF(ROW()>COUNTA(B:E), "", INDEX(B:B,ROW()-COUNTA(E:E))))=0, "", IF(ROW()<=COUNTA(E:E), INDEX(E:E,ROW()), IF(ROW()>COUNTA(B:E), "", INDEX(B:B,ROW()-COUNTA(E:E)))))} | J355: {=IF(IF(ROW()<=COUNTA(F:F), INDEX(F:F,ROW()), IF(ROW()>COUNTA(C:F), "", INDEX(C:C,ROW()-COUNTA(F:F))))=0, "", IF(ROW()<=COUNTA(F:F), INDEX(F:F,ROW()), IF(ROW()>COUNTA(C:F), "", INDEX(C:C,ROW()-COUNTA(F:F)))))}
C356: =Credit!F357 -> 0 | D356: 0 | E356: 0 | F356: =Payment!F357 -> 0 | H356: {=IF(IF(ROW()<=COUNTA(D:D), INDEX(D:D,ROW()), IF(ROW()>COUNTA(A:D), "", INDEX(A:A,ROW()-COUNTA(D:D))))=0, "", IF(ROW()<=COUNTA(D:D), INDEX(D:D,ROW()), IF(ROW()>COUNTA(A:D), "", INDEX(A:A,ROW()-COUNTA(D:D)))))} | I356: {=IF(IF(ROW()<=COUNTA(E:E), INDEX(E:E,ROW()), IF(ROW()>COUNTA(B:E), "", INDEX(B:B,ROW()-COUNTA(E:E))))=0, "", IF(ROW()<=COUNTA(E:E), INDEX(E:E,ROW()), IF(ROW()>COUNTA(B:E), "", INDEX(B:B,ROW()-COUNTA(E:E)))))} | J356: {=IF(IF(ROW()<=COUNTA(F:F), INDEX(F:F,ROW()), IF(ROW()>COUNTA(C:F), "", INDEX(C:C,ROW()-COUNTA(F:F))))=0, "", IF(ROW()<=COUNTA(F:F), INDEX(F:F,ROW()), IF(ROW()>COUNTA(C:F), "", INDEX(C:C,ROW()-COUNTA(F:F)))))}
...

Sheet Sheet1
B9: Customer Payment History
B11: Certificate Number: | C11: 237566
B13: Isabel Rios
B14: 14710 Hutchcroft St, La Puente, CA 91744
B16: Total Payments | C16: =Totals!L6 -> 0
B17: Total Credits | C17: =Totals!L7 -> 0
B18: Total Payments Less Credits | C18: =GrandTotal -> 0
B20: Date Received or Credited | C20: Amount Received or Credited | D20: Check Number
B21: {=Sort}
