Workbook

Sheet Nov 2009 IRA 
A1: Home Protection Associates
A2: Payroll 11/14/2009 | B2: employee contribution | C2: Employer Contribution | D2: Amount Due
A3: Crostic, Deanna | B3: 99.4 | C3: 42.6
A4: Darr, Melanie | B4: 24.6 | C4: 24.6
A5: Gandara, Araceli | B5: 18.6 | C5: 18.6
A6: Martinez-Aguila, Carmen | B6: 31.98 | C6: 31.98
B7: =SUM(B3:B6) -> 174.58 | C7: =SUM(C3:C6) -> 117.78 | D7: =SUM(B7:C7) -> 292.36
A10: Payroll 11/21/2009 | B10: Employee Contribution | C10: Employer Contribution | D10: Amount Due
A11: Crostic, Deanna | B11: 99.4 | C11: 42.6
A12: Darr, Melanie | B12: 24.6 | C12: 24.6
A13: Gandara, Araceli | B13: 18.6 | C13: 18.6
A14: Martinez-Aguila, Carmen | B14: 32.88 | C14: 32.88
B15: =SUM(B11:B14) -> 175.48 | C15: =SUM(C11:C14) -> 118.68 | D15: =SUM(B15:C15) -> 294.16
A17: Payroll 11/28/2009 | B17: Employee Contribution | C17: Employer Contribution | D17: Amount Due
A18: Crostic, Deanna | B18: 99.4 | C18: 42.6
A19: Darr, Melanie | B19: 24.6 | C19: 24.6
A20: Gandara, Araceli | B20: 18.6 | C20: 18.6
A21: Martinez-Aguila, Carmen | B21: 31.98 | C21: 31.98
B22: =SUM(B18:B21) -> 174.58 | C22: =SUM(C18:C21) -> 117.78 | D22: =SUM(B22:C22) -> 292.36
A24: Balance due Nov 2009 | D24: =D7+D15+D22 -> 878.88

Sheet Dec 2009 IRA
A1: Home Protection Associates
A2: Payroll 12/07/2009 | B2: employee contribution | C2: Employer Contribution | D2: Amount Due
A3: Crostic, Deanna | B3: 124.25 | C3: 53.25
A4: Darr, Melanie | B4: 24.6 | C4: 24.6
A5: Gandara, Araceli | B5: 18.6 | C5: 18.6
A6: Martinez-Aguila, Carmen | B6: 32.38 | C6: 32.38
B7: =SUM(B3:B6) -> 199.83 | C7: =SUM(C3:C6) -> 128.83 | D7: =SUM(B7:C7) -> 328.66
A10: Payroll 12/14/2009 | B10: Employee Contribution | C10: Employer Contribution | D10: Amount Due
A11: Crostic, Deanna | B11: 99.4 | C11: 42.6
A12: Darr, Melanie | B12: 24.6 | C12: 24.6
A13: Gandara, Araceli | B13: 18.6 | C13: 18.6
A14: Martinez-Aguila, Carmen | B14: 31.98 | C14: 31.98
B15: =SUM(B11:B14) -> 174.58 | C15: =SUM(C11:C14) -> 117.78 | D15: =SUM(B15:C15) -> 292.36
A17: Payroll 12/18/2009 | B17: Employee Contribution | C17: Employer Contribution | D17: Amount Due | E17: bonuses
A18: Crostic, Deanna | B18: 54.46 | C18: 23.24
A19: Darr, Melanie | B19: 17.83 | C19: 17.83
A20: Gandara, Araceli | B20: 17.47 | C20: 17.47
A21: Martinez-Aguila, Carmen | B21: 16.79 | C21: 16.79
B22: =SUM(B18:B21) -> 106.55 | C22: =SUM(C18:C21) -> 75.33 | D22: =SUM(B22:C22) -> 181.88
A24: Payroll 12/21/2009 | B24: Employee Contribution | C24: Employer Contribution | D24: Amount Due
A25: Crostic, Deanna | B25: 99.4 | C25: 42.6
A26: Darr, Melanie | B26: 24.6 | C26: 24.6
A27: Gandara, Araceli | B27: 18.6 | C27: 18.6
A28: Martinez-Aguila, Carmen | B28: 31.98 | C28: 31.98
B29: =SUM(B25:B28) -> 174.58 | C29: =SUM(C25:C28) -> 117.78 | D29: =SUM(B29:C29) -> 292.36
A31: Payroll 12/28/2009 | B31: Employee Contribution | C31: Employer Contribution | D31: Amount Due
A32: Crostic, Deanna | B32: 99.4 | C32: 42.6
A33: Darr, Melanie | B33: 24.6 | C33: 24.6
A34: Gandara, Araceli | B34: 18.6 | C34: 18.6
A35: Martinez-Aguila, Carmen | B35: 31.98 | C35: 31.98
B36: =SUM(B32:B35) -> 174.58 | C36: =SUM(C32:C35) -> 117.78 | D36: =SUM(B36:C36) -> 292.36
A38: Balance due Dec 2009 | D38: =D7+D15+D22+D29+D36 -> 1387.62

Sheet Sheet3

Sheet Jan 2010
A1: Home Protection Associates
A2: Payroll 01/04/2010 | B2: employee contribution | C2: Employer Contribution | D2: Amount Due
A3: Crostic, Deanna | B3: 99.4 | C3: 42.6
A4: Darr, Melanie | B4: 24.6 | C4: 24.6
A5: Gandara, Araceli | B5: 18.6 | C5: 18.6
A6: Martinez-Aguila, Carmen | B6: 31.98 | C6: 31.98
B7: =SUM(B3:B6) -> 174.58 | C7: =SUM(C3:C6) -> 117.78 | D7: =SUM(B7:C7) -> 292.36
A10: Payroll 01/11/2010 | B10: Employee Contribution | C10: Employer Contribution | D10: Amount Due
A11: Crostic, Deanna | B11: 99.4 | C11: 42.6
A12: Darr, Melanie | B12: 24.6 | C12: 24.6
A13: Gandara, Araceli | B13: 18.6 | C13: 18.6
A14: Martinez-Aguila, Carmen | B14: 31.98 | C14: 31.98
B15: =SUM(B11:B14) -> 174.58 | C15: =SUM(C11:C14) -> 117.78 | D15: =SUM(B15:C15) -> 292.36
A18: Payroll 01/16/2010 | B18: Employee Contribution | C18: Employer Contribution | D18: Amount Due
A19: Crostic, Deanna | B19: 99.4 | C19: 42.6
A20: Darr, Melanie | B20: 24.6 | C20: 24.6
A21: Gandara, Araceli | B21: 18.6 | C21: 18.6
A22: Martinez-Aguila, Carmen | B22: 31.98 | C22: 31.98
B23: =SUM(B19:B22) -> 174.58 | C23: =SUM(C19:C22) -> 117.78 | D23: =SUM(B23:C23) -> 292.36
A25: Payroll 01/25/2010 | B25: Employee Contribution | C25: Employer Contribution | D25: Amount Due
A26: Crostic, Deanna | B26: 99.4 | C26: 42.6
A27: Darr, Melanie | B27: 24.6 | C27: 24.6
A28: Gandara, Araceli | B28: 18.6 | C28: 18.6
A29: Martinez-Aguila, Carmen | B29: 31.98 | C29: 31.98
B30: =SUM(B26:B29) -> 174.58 | C30: =SUM(C26:C29) -> 117.78 | D30: =SUM(B30:C30) -> 292.36
A32: Balance due Jan 2010 | D32: =D7+D15+D23+D30 -> 1169.44

Sheet Feb 2010
A1: Home Protection Associates
A2: Payroll 02/01/2010 | B2: employee contribution | C2: Employer Contribution | D2: Amount Due
A3: Crostic, Deanna | B3: 99.4 | C3: 42.6
A4: Darr, Melanie | B4: 24.6 | C4: 24.6
A5: Gandara, Araceli | B5: 18.6 | C5: 18.6
A6: Martinez-Aguila, Carmen | B6: 31.98 | C6: 31.98
B7: =SUM(B3:B6) -> 174.58 | C7: =SUM(C3:C6) -> 117.78 | D7: =SUM(B7:C7) -> 292.36
A10: Payroll 02/08/2010 | B10: Employee Contribution | C10: Employer Contribution | D10: Amount Due
A11: Crostic, Deanna | B11: 99.4 | C11: 42.6
A12: Darr, Melanie | B12: 24.6 | C12: 24.6
A13: Gandara, Araceli | B13: 18.6 | C13: 18.6
A14: Martinez-Aguila, Carmen | B14: 31.98 | C14: 31.98
B15: =SUM(B11:B14) -> 174.58 | C15: =SUM(C11:C14) -> 117.78 | D15: =SUM(B15:C15) -> 292.36
A18: Payroll 02/13/2010 | B18: Employee Contribution | C18: Employer Contribution | D18: Amount Due
A19: Crostic, Deanna | B19: 99.4 | C19: 42.6
A20: Darr, Melanie | B20: 24.6 | C20: 24.6
A21: Gandara, Araceli | B21: 18.6 | C21: 18.6
A22: Martinez-Aguila, Carmen | B22: 31.98 | C22: 31.98
B23: =SUM(B19:B22) -> 174.58 | C23: =SUM(C19:C22) -> 117.78 | D23: =SUM(B23:C23) -> 292.36
A25: Payroll 02/22/2010 | B25: Employee Contribution | C25: Employer Contribution | D25: Amount Due
A26: Crostic, Deanna | B26: 119.28 | C26: 51.12
A27: Darr, Melanie | B27: 24.6 | C27: 24.6
A28: Gandara, Araceli | B28: 18.6 | C28: 18.6
A29: Martinez-Aguila, Carmen | B29: 31.98 | C29: 31.98
B30: =SUM(B26:B29) -> 194.46 | C30: =SUM(C26:C29) -> 126.3 | D30: =SUM(B30:C30) -> 320.76
A32: Balance due Feb 2010 | D32: =D7+D15+D23+D30 -> 1197.84

Sheet March 2010 
A1: Home Protection Associates
A2: Payroll 03/08/2010 | B2: employee contribution | C2: Employer Contribution | D2: Amount Due
A3: Crostic, Deanna | B3: 99.4 | C3: 42.6
A4: Darr, Melanie | B4: 24.6 | C4: 24.6
A5: Gandara, Araceli | B5: 18.6 | C5: 18.6
A6: Martinez-Aguila, Carmen | B6: 31.98 | C6: 31.98
B7: =SUM(B3:B6) -> 174.58 | C7: =SUM(C3:C6) -> 117.78 | D7: =SUM(B7:C7) -> 292.36
A10: Payroll 03/15/2010 | B10: Employee Contribution | C10: Employer Contribution | D10: Amount Due
A11: Crostic, Deanna | B11: 99.4 | C11: 42.6
A12: Darr, Melanie | B12: 24.6 | C12: 24.6
A13: Gandara, Araceli | B13: 18.6 | C13: 18.6
A14: Martinez-Aguila, Carmen | B14: 31.98 | C14: 31.98
B15: =SUM(B11:B14) -> 174.58 | C15: =SUM(C11:C14) -> 117.78 | D15: =SUM(B15:C15) -> 292.36
A18: Payroll 03/22/2010 | B18: Employee Contribution | C18: Employer Contribution | D18: Amount Due
A19: Crostic, Deanna | B19: 99.4 | C19: 42.6
A20: Darr, Melanie | B20: 24.6 | C20: 24.6
A21: Gandara, Araceli | B21: 18.6 | C21: 18.6
A22: Martinez-Aguila, Carmen | B22: 31.98 | C22: 31.98
B23: =SUM(B19:B22) -> 174.58 | C23: =SUM(C19:C22) -> 117.78 | D23: =SUM(B23:C23) -> 292.36
A25: Payroll 03/29/2010 | B25: Employee Contribution | C25: Employer Contribution | D25: Amount Due
A26: Crostic, Deanna | B26: 99.4 | C26: 51.12
A27: Darr, Melanie | B27: 24.6 | C27: 24.6
A28: Gandara, Araceli | B28: 18.6 | C28: 18.6
A29: Martinez-Aguila, Carmen | B29: 31.98 | C29: 31.98
B30: =SUM(B26:B29) -> 174.58 | C30: =SUM(C26:C29) -> 126.3 | D30: =SUM(B30:C30) -> 300.88
A32: Balance due March 2010 | D32: =D7+D15+D23+D30 -> 1177.96

Sheet April 2010
A1: Home Protection Associates
A2: Payroll 04/05/2010 | B2: employee contribution | C2: Employer Contribution | D2: Amount Due
A3: Crostic, Deanna | B3: 99.4 | C3: 42.6
A4: Darr, Melanie | B4: 24.6 | C4: 24.6
A5: Gandara, Araceli | B5: 18.6 | C5: 18.6
A6: Martinez-Aguila, Carmen | B6: 31.98 | C6: 31.98
B7: =SUM(B3:B6) -> 174.58 | C7: =SUM(C3:C6) -> 117.78 | D7: =SUM(B7:C7) -> 292.36
A10: Payroll 04/12/2010 | B10: Employee Contribution | C10: Employer Contribution | D10: Amount Due
A11: Crostic, Deanna | B11: 99.4 | C11: 42.6
A12: Darr, Melanie | B12: 24.6 | C12: 24.6
A13: Gandara, Araceli | B13: 18.6 | C13: 18.6
A14: Martinez-Aguila, Carmen | B14: 31.98 | C14: 31.98
B15: =SUM(B11:B14) -> 174.58 | C15: =SUM(C11:C14) -> 117.78 | D15: =SUM(B15:C15) -> 292.36
A18: Payroll 04/19/2010 | B18: Employee Contribution | C18: Employer Contribution | D18: Amount Due
A19: Crostic, Deanna | B19: 99.4 | C19: 42.6
A20: Darr, Melanie | B20: 24.6 | C20: 24.6
A21: Gandara, Araceli | B21: 18.6 | C21: 18.6
A22: Martinez-Aguila, Carmen | B22: 31.98 | C22: 31.98
B23: =SUM(B19:B22) -> 174.58 | C23: =SUM(C19:C22) -> 117.78 | D23: =SUM(B23:C23) -> 292.36
A25: Payroll 04/26/2010 | B25: Employee Contribution | C25: Employer Contribution | D25: Amount Due
A26: Crostic, Deanna | B26: 99.4 | C26: 42.6
A27: Darr, Melanie | B27: 24.6 | C27: 24.6
A28: Gandara, Araceli | B28: 18.6 | C28: 18.6
A29: Martinez-Aguila, Carmen | B29: 31.98 | C29: 31.98
B30: =SUM(B26:B29) -> 174.58 | C30: =SUM(C26:C29) -> 117.78 | D30: =SUM(B30:C30) -> 292.36
A32: Balance due April 2010 | D32: =D7+D15+D23+D30 -> 1169.44

Sheet May 2010
A1: Home Protection Associates
A2: Payroll 05/03/2010 | B2: employee contribution | C2: Employer Contribution | D2: Amount Due
A3: Crostic, Deanna | B3: 99.4 | C3: 42.6
A4: Darr, Melanie | B4: 24.6 | C4: 24.6
A5: Gandara, Araceli | B5: 18.6 | C5: 18.6
A6: Martinez-Aguila, Carmen | B6: 31.98 | C6: 31.98
B7: =SUM(B3:B6) -> 174.58 | C7: =SUM(C3:C6) -> 117.78 | D7: =SUM(B7:C7) -> 292.36
A10: Payroll 05/08/2010 | B10: Employee Contribution | C10: Employer Contribution | D10: Amount Due
A11: Crostic, Deanna | B11: 99.4 | C11: 42.6
A12: Darr, Melanie | B12: 24.6 | C12: 24.6
A13: Gandara, Araceli | B13: 18.6 | C13: 18.6
A14: Martinez-Aguila, Carmen | B14: 31.98 | C14: 31.98
B15: =SUM(B11:B14) -> 174.58 | C15: =SUM(C11:C14) -> 117.78 | D15: =SUM(B15:C15) -> 292.36
A18: Payroll 05/24/2010 | B18: Employee Contribution | C18: Employer Contribution | D18: Amount Due
A19: Crostic, Deanna | B19: 99.4 | C19: 42.6
A20: Darr, Melanie | B20: 24.6 | C20: 24.6
A21: Gandara, Araceli | B21: 11.63 | C21: 18.6
A22: Martinez-Aguila, Carmen | B22: 31.98 | C22: 31.98
B23: =SUM(B19:B22) -> 167.61 | C23: =SUM(C19:C22) -> 117.78 | D23: =SUM(B23:C23) -> 285.39
A25: Payroll 05/29/2010 | B25: Employee Contribution | C25: Employer Contribution | D25: Amount Due
A26: Crostic, Deanna | B26: 99.4 | C26: 42.6
A27: Darr, Melanie | B27: 24.6 | C27: 24.6
A28: Gandara, Araceli | B28: 19.3 | C28: 18.6
A29: Martinez-Aguila, Carmen | B29: 31.98 | C29: 31.98
B30: =SUM(B26:B29) -> 175.28 | C30: =SUM(C26:C29) -> 117.78 | D30: =SUM(B30:C30) -> 293.06
A32: Balance due May 2010 | D32: =D7+D15+D23+D30 -> 1163.17

Sheet June 2010 
A1: Home Protection Associates
A2: Payroll 6/3//2010 | B2: employee contribution | C2: Employer Contribution | D2: Amount Due
A3: Crostic, Deanna | B3: 99.4 | C3: 42.6
A4: Darr, Melanie | B4: 24.6 | C4: 24.6
A5: Gandara, Araceli | B5: 18.6 | C5: 18.6
A6: Martinez-Aguila, Carmen | B6: 31.98 | C6: 31.98
B7: =SUM(B3:B6) -> 174.58 | C7: =SUM(C3:C6) -> 117.78 | D7: =SUM(B7:C7) -> 292.36
A10: Payroll 6/10/2010 | B10: Employee Contribution | C10: Employer Contribution | D10: Amount Due
A11: Crostic, Deanna | B11: 99.4 | C11: 42.6
A12: Darr, Melanie | B12: 20.6 | C12: 24.6
A13: Gandara, Araceli | B13: 18.02 | C13: 18.6
A14: Martinez-Aguila, Carmen | B14: 31.98 | C14: 31.98
B15: =SUM(B11:B14) -> 170 | C15: =SUM(C11:C14) -> 117.78 | D15: =SUM(B15:C15) -> 287.78
A17: Payroll 6/17/2010 | B17: Employee Contribution | C17: Employer Contribution | D17: Amount Due
A18: Crostic, Deanna | B18: 99.4 | C18: 42.6
A19: Darr, Melanie | B19: 24.6 | C19: 24.6
A20: Gandara, Araceli | B20: 19.07 | C20: 19.07
A21: Martinez-Aguila, Carmen | B21: 31.98 | C21: 31.98
B22: =SUM(B18:B21) -> 175.05 | C22: =SUM(C18:C21) -> 118.25 | D22: =SUM(B22:C22) -> 293.3
A24: Payroll 6/24/2010 | B24: Employee Contribution | C24: Employer Contribution | D24: Amount Due
A25: Crostic, Deanna | B25: 99.4 | C25: 42.6
A26: Darr, Melanie | B26: 20.6 | C26: 20.6
A27: Gandara, Araceli | B27: 18.02 | C27: 18.02
A28: Martinez-Aguila, Carmen | B28: 31.98 | C28: 31.98
B29: =SUM(B25:B28) -> 170 | C29: =SUM(C25:C28) -> 113.2 | D29: =SUM(B29:C29) -> 283.2
A31: Payroll 6/30/2010 | B31: Employee Contribution | C31: Employer Contribution | D31: Amount Due
A32: Crostic, Deanna | B32: 99.4 | C32: 42.6
A33: Darr, Melanie | B33: 19.68 | C33: 19.68
A34: Gandara, Araceli | B34: 18.6 | C34: 18.6
A35: Martinez-Aguila, Carmen | B35: 31.98 | C35: 31.98
B36: =SUM(B32:B35) -> 169.66 | C36: =SUM(C32:C35) -> 112.86 | D36: =SUM(B36:C36) -> 282.52
A38: Balance due June 2010 | D38: =D7+D15+D29+D36+D22 -> 1439.16

Sheet July 2010 
A1: Home Protection Associates
A2: Payroll 7/3/2010 | B2: employee contribution | C2: Employer Contribution | D2: Amount Due
A3: Crostic, Deanna | B3: 99.4 | C3: 42.6
A4: Darr, Melanie | B4: 19.68 | C4: 19.68
A5: Gandara, Araceli | B5: 18.6 | C5: 18.6
A6: Martinez-Aguila, Carmen | B6: 31.98 | C6: 31.98
B7: =SUM(B3:B6) -> 169.66 | C7: =SUM(C3:C6) -> 112.86 | D7: =SUM(B7:C7) -> 282.52
A10: Payroll/ 7/10/2010 | B10: Employee Contribution | C10: Employer Contribution | D10: Amount Due
A11: Crostic, Deanna | B11: 99.4 | C11: 42.6
A12: Darr, Melanie | B12: 19.68 | C12: 19.68
A13: Gandara, Araceli | B13: 18.6 | C13: 18.6
A14: Martinez-Aguila, Carmen | B14: 31.98 | C14: 31.98
B15: =SUM(B11:B14) -> 169.66 | C15: =SUM(C11:C14) -> 112.86 | D15: =SUM(B15:C15) -> 282.52
A18: Payroll 7/17/2010 | B18: Employee Contribution | C18: Employer Contribution | D18: Amount Due
A19: Crostic, Deanna | B19: 99.4 | C19: 42.6
A20: Darr, Melanie | B20: 9.23 | C20: 9.23
A21: Gandara, Araceli | B21: 18.14 | C21: 18.14
A22: Martinez-Aguila, Carmen | B22: 31.98 | C22: 31.98
B23: =SUM(B19:B22) -> 158.75 | C23: =SUM(C19:C22) -> 101.95 | D23: =SUM(B23:C23) -> 260.7
A25: Payroll 7/24/2010 | B25: Employee Contribution | C25: Employer Contribution | D25: Amount Due
A26: Crostic, Deanna | B26: 99.4 | C26: 42.6
A27: Darr, Melanie
A28: Gandara, Araceli | B28: 20.4 | C28: 20.4
A29: Martinez-Aguila, Carmen | B29: 33.18 | C29: 33.18
B30: =SUM(B26:B29) -> 152.98 | C30: =SUM(C26:C29) -> 96.18 | D30: =SUM(B30:C30) -> 249.16
A32: Balance due July 2010 | D32: =D7+D15+D23+D30 -> 1074.9

Sheet August 2010
A1: Home Protection Associates
A2: Payroll /2010 | B2: employee contribution | C2: Employer Contribution | D2: Amount Due
A3: Crostic, Deanna | B3: 99.4 | C3: 42.6
A4: Darr, Melanie
A5: Gandara, Araceli | B5: 20.4 | C5: 20.4
A6: Martinez-Aguila, Carmen | B6: 33.18 | C6: 33.18
D7: =SUM(B3:C6) -> 249.16
A10: Payroll/ /2010 | B10: Employee Contribution | C10: Employer Contribution | D10: Amount Due
A11: Crostic, Deanna | B11: 99.4 | C11: 42.6
A12: Darr, Melanie
A13: Gandara, Araceli | B13: 20.4 | C13: 20.4
A14: Martinez-Aguila, Carmen | B14: 33.18 | C14: 33.18
D15: =SUM(B11:C14) -> 249.16
A18: Payroll /2010 | B18: Employee Contribution | C18: Employer Contribution | D18: Amount Due
A19: Crostic, Deanna | B19: 99.4 | C19: 42.6
A20: Darr, Melanie
A21: Gandara, Araceli | B21: 20.4 | C21: 20.4
A22: Martinez-Aguila, Carmen | B22: 33.18 | C22: 33.18
D23: =SUM(B19:C22) -> 249.16
A25: Payroll 2010 | B25: Employee Contribution | C25: Employer Contribution | D25: Amount Due
A26: Crostic, Deanna | B26: 99.4 | C26: 42.6
A27: Darr, Melanie
A28: Gandara, Araceli | B28: 20.4 | C28: 20.4
A29: Martinez-Aguila, Carmen | B29: 33.18 | C29: 33.18
D30: =SUM(B26:C29) -> 249.16
A32: Balance due August 2010 | D32: =D7+D15+D23+D30 -> 996.64

Sheet Sept 2010
A1: Home Protection Associates
A2: Payroll 9/3/2010 | B2: employee contribution | C2: Employer Contribution | D2: Amount Due
A3: Crostic, Deanna | B3: 124.25 | C3: 53.25
A4: Darr, Melanie | B4: 18.27 | C4: 18.27
A5: Gandara, Araceli | B5: 16.83 | C5: 16.83
A6: Martinez-Aguila, Carmen | B6: 33.18 | C6: 33.18
D7: =SUM(B3:C6) -> 314.06
A10: Payroll 9/13 /2010 | B10: Employee Contribution | C10: Employer Contribution | D10: Amount Due
A11: Crostic, Deanna | B11: 99.4 | C11: 42.6
A12: Darr, Melanie | B12: 23.49 | C12: 23.49
A13: Gandara, Araceli | B13: 20.4 | C13: 20.4
A14: Martinez-Aguila, Carmen | B14: 33.18 | C14: 33.18
D15: =SUM(B11:C14) -> 296.14
A18: Payroll 9/20/2010 | B18: Employee Contribution | C18: Employer Contribution | D18: Amount Due
A19: Crostic, Deanna | B19: 99.4 | C19: 42.6
A20: Darr, Melanie | B20: 21.21 | C20: 21.21
A21: Gandara, Araceli | B21: 19.64 | C21: 19.64
A22: Martinez-Aguila, Carmen | B22: 33.18 | C22: 33.18
D23: =SUM(B19:C22) -> 290.06
A25: Payroll 9/27/2010 | B25: Employee Contribution | C25: Employer Contribution | D25: Amount Due
A26: Crostic, Deanna | B26: 99.4 | C26: 42.6
A27: Darr, Melanie | B27: 23.49 | C27: 23.49
A28: Gandara, Araceli | B28: 19.89 | C28: 19.89
A29: Martinez-Aguila, Carmen | B29: 33.18 | C29: 33.18
D30: =SUM(B26:C29) -> 295.12
A32: Balance due Sept 2010 | D32: =D7+D15+D23+D30 -> 1195.38

Sheet Oct 2010 
A1: Home Protection Associates
A2: Payroll 10/04/2010 | B2: employee contribution | C2: Employer Contribution | D2: Amount Due
A3: Crostic, Deanna | B3: 99.4 | C3: 42.6
A4: Darr, Melanie | B4: 23.49 | C4: 23.49
A5: Gandara, Araceli | B5: 18.74 | C5: 18.74
A6: Martinez-Aguila, Carmen | B6: 33.18 | C6: 33.18
D7: =SUM(B3:C6) -> 292.82
A10: Payroll 10/08/2010 | B10: Employee Contribution | C10: Employer Contribution | D10: Amount Due
A11: Crostic, Deanna | B11: 124.25 | C11: 53.25
A12: Darr, Melanie | B12: 23.49 | C12: 23.49
A13: Gandara, Araceli | B13: 20.4 | C13: 20.4
A14: Martinez-Aguila, Carmen | B14: 33.18 | C14: 33.18
D15: =SUM(B11:C14) -> 331.64
A18: Payroll 10/18/2010 | B18: Employee Contribution | C18: Employer Contribution | D18: Amount Due
A19: Crostic, Deanna | B19: 124.25 | C19: 53.25
A20: Darr, Melanie | B20: 18.27 | C20: 18.27
A21: Gandara, Araceli | B21: 20.4 | C21: 20.4
A22: Martinez-Aguila, Carmen | B22: 33.8 | C22: 33.8
D23: =SUM(B19:C22) -> 322.44
A25: Payroll 10/25/2010 | B25: Employee Contribution | C25: Employer Contribution | D25: Amount Due
A26: Crostic, Deanna | B26: 99.4 | C26: 42.6
A27: Darr, Melanie | B27: 23.49 | C27: 23.49
A28: Gandara, Araceli | B28: 20.4 | C28: 20.4
A29: Martinez-Aguila, Carmen | B29: 33.18 | C29: 33.18
D30: =SUM(B26:C29) -> 296.14
A32: Balance due Oct 2010 | D32: =D7+D15+D23+D30 -> 1243.04

Sheet Nov 2010
A1: Home Protection Associates
A2: Payroll 11/01/2010 | B2: employee contribution | C2: Employer Contribution | D2: Amount Due
A3: Crostic, Deanna | B3: 99.4 | C3: 42.6
A4: Darr, Melanie | B4: 23.49 | C4: 23.49
A5: Gandara, Araceli | B5: 18.36 | C5: 18.36
A6: Martinez-Aguila, Carmen | B6: 33.18 | C6: 33.18
D7: =SUM(B3:C6) -> 292.06
A10: Payroll 11/08/2010 | B10: Employee Contribution | C10: Employer Contribution | D10: Amount Due
A11: Crostic, Deanna | B11: 124.25 | C11: 53.25
A12: Darr, Melanie | B12: 18.24 | C12: 18.27
A13: Gandara, Araceli | B13: 20.4 | C13: 20.4
A14: Martinez-Aguila, Carmen | B14: 33.18 | C14: 33.18
D15: =SUM(B11:C14) -> 321.17
A18: Payroll 11/15/2010 | B18: Employee Contribution | C18: Employer Contribution | D18: Amount Due
A19: Crostic, Deanna | B19: 99.4 | C19: 42.6
A20: Darr, Melanie | B20: 23.49 | C20: 23.49
A21: Gandara, Araceli | B21: 20.4 | C21: 20.4
A22: Martinez-Aguila, Carmen | B22: 33.8 | C22: 33.8
D23: =SUM(B19:C22) -> 297.38
A25: Payroll 11/22/2010 | B25: Employee Contribution | C25: Employer Contribution | D25: Amount Due
A26: Crostic, Deanna | B26: 99.4 | C26: 42.6
A27: Darr, Melanie | B27: 23.49 | C27: 23.49
A28: Gandara, Araceli | B28: 20.4 | C28: 20.4
A29: Martinez-Aguila, Carmen | B29: 33.18 | C29: 33.18
D30: =SUM(B26:C29) -> 296.14
A32: Balance due Nov 2010 | D32: =D7+D15+D23+D30 -> 1206.75

Sheet Dec 2010
A1: Home Protection Associates
A2: Payroll 12/6/10 | B2: employee contribution | C2: Employer Contribution | D2: Amount Due
A3: Crostic, Deanna | B3: 99.4 | C3: 42.6
A4: Darr, Melanie | B4: 23.49 | C4: 23.49
A5: Gandara, Araceli | B5: 20.15 | C5: 20.15
A6: Martinez-Aguila, Carmen | B6: 33.18 | C6: 33.18
D7: =SUM(B3:C6) -> 295.64
A10: Payroll 12/13/2010 | B10: Employee Contribution | C10: Employer Contribution | D10: Amount Due
A11: Crostic, Deanna | B11: 99.4 | C11: 42.6
A12: Darr, Melanie | B12: 23.49 | C12: 23.49
A13: Gandara, Araceli | B13: 20.27 | C13: 20.27
A14: Martinez-Aguila, Carmen | B14: 33.18 | C14: 33.18
D15: =SUM(B11:C14) -> 295.88
A18: Payroll 12/20/2010 | B18: Employee Contribution | C18: Employer Contribution | D18: Amount Due
A19: Crostic, Deanna | B19: 111.83 | C19: 47.93
A20: Darr, Melanie | B20: 23.16 | C20: 23.49
A21: Gandara, Araceli | B21: 20.4 | C21: 20.4
A22: Martinez-Aguila, Carmen | B22: 33.8 | C22: 33.8
D23: =SUM(B19:C22) -> 314.81
A25: Payroll 11/22/2010 | B25: Employee Contribution | C25: Employer Contribution | D25: Amount Due
A26: Crostic, Deanna | B26: 111.83 | C26: 47.93
A27: Darr, Melanie | B27: 22.19 | C27: 22.19
A28: Gandara, Araceli | B28: 19.38 | C28: 19.38
A29: Martinez-Aguila, Carmen | B29: 33.18 | C29: 33.18
D30: =SUM(B26:C29) -> 309.26
A32: Balance due Dec 2010 | D32: =D7+D15+D23+D30 -> 1215.59

Sheet Jan 2011
A1: Home Protection Associates
A2: Payroll 1/10/11 | B2: employee contribution | C2: Employer Contribution | D2: Amount Due
A3: Crostic, Deanna | B3: 99.4 | C3: 42.6
A4: Darr, Melanie | B4: 22.51 | C4: 22.51
A5: Gandara, Araceli | B5: 18.36 | C5: 18.36
A6: Martinez-Aguila, Carmen | B6: 33.18 | C6: 33.18
D7: =SUM(B3:C6) -> 290.1
A10: Payroll 1/14/11 | B10: Employee Contribution | C10: Employer Contribution | D10: Amount Due
A11: Crostic, Deanna | B11: 111.83 | C11: 47.93
A12: Darr, Melanie | B12: 23.49 | C12: 23.49
A13: Gandara, Araceli | B13: 20.4 | C13: 20.4
A14: Martinez-Aguila, Carmen | B14: 33.18 | C14: 33.18
D15: =SUM(B11:C14) -> 313.9
A18: Payroll 1/22/11 | B18: Employee Contribution | C18: Employer Contribution | D18: Amount Due
A19: Crostic, Deanna | B19: 99.4 | C19: 42.6
A20: Darr, Melanie | B20: 23.16 | C20: 23.49
A21: Gandara, Araceli | B21: 20.4 | C21: 20.4
A22: Martinez-Aguila, Carmen | B22: 33.18 | C22: 33.18
D23: =SUM(B19:C22) -> 295.81
A25: Payroll 1/29/11 | B25: Employee Contribution | C25: Employer Contribution | D25: Amount Due
A26: Crostic, Deanna | B26: 99.4 | C26: 42.6
A27: Darr, Melanie | B27: 23.49 | C27: 23.49
A28: Gandara, Araceli | B28: 20.4 | C28: 20.4
A29: Martinez-Aguila, Carmen | B29: 33.39 | C29: 33.39
D30: =SUM(B26:C29) -> 296.56
A32: Balance due Jan 2011 | D32: =D7+D15+D23+D30 -> 1196.37

Sheet Feb 2011 
A1: Home Protection Associates
A2: Payroll 2/3/11 | B2: employee contribution | C2: Employer Contribution | D2: Amount Due
A3: Crostic, Deanna | B3: 124.25 | C3: 53.25
A4: Darr, Melanie | B4: 23.49 | C4: 23.49
A5: Gandara, Araceli | B5: 20.4 | C5: 20.4
A6: Martinez-Aguila, Carmen | B6: 33.18 | C6: 33.18
D7: =SUM(B3:C6) -> 331.64
A10: Payroll 2/10/11 | B10: Employee Contribution | C10: Employer Contribution | D10: Amount Due
A11: Crostic, Deanna | B11: 99.4 | C11: 42.6
A12: Darr, Melanie | B12: 22.19 | C12: 22.19
A13: Gandara, Araceli | B13: 20.59 | C13: 20.59
A14: Martinez-Aguila, Carmen | B14: 33.18 | C14: 33.18
D15: =SUM(B11:C14) -> 293.92
A18: Payroll 2/16/11 | B18: Employee Contribution | C18: Employer Contribution | D18: Amount Due
A19: Crostic, Deanna | B19: 99.4 | C19: 42.6
A20: Darr, Melanie | B20: 23.49 | C20: 23.49
A21: Gandara, Araceli | B21: 18.36 | C21: 18.36
A22: Martinez-Aguila, Carmen | B22: 33.18 | C22: 33.18
D23: =SUM(B19:C22) -> 292.06
A25: Payroll 2/24/11 | B25: Employee Contribution | C25: Employer Contribution | D25: Amount Due
A26: Crostic, Deanna | B26: 124.25 | C26: 53.25
A27: Darr, Melanie | B27: 22.67 | C27: 22.67
A28: Gandara, Araceli | B28: 20.4 | C28: 20.4
A29: Martinez-Aguila, Carmen | B29: 33.18 | C29: 33.18
D30: =SUM(B26:C29) -> 330
A32: Balance dueFeb2011 | D32: =D7+D15+D23+D30 -> 1247.62

Sheet Mar 2011
A1: Home Protection Associates
A2: Payroll 3/7/11 | B2: employee contribution | C2: Employer Contribution | D2: Amount Due
A3: Crostic, Deanna | B3: 124.25 | C3: 53.25
A4: Darr, Melanie | B4: 22.84 | C4: 22.84
A5: Gandara, Araceli | B5: 20.4 | C5: 20.4
A6: Martinez-Aguila, Carmen | B6: 33.18 | C6: 33.18
D7: =SUM(B3:C6) -> 330.34
A10: Payroll 3/14/11 | B10: Employee Contribution | C10: Employer Contribution | D10: Amount Due
A11: Crostic, Deanna | B11: 99.4 | C11: 42.6
A12: Darr, Melanie | B12: 23.49 | C12: 23.49
A13: Gandara, Araceli | B13: 20.4 | C13: 20.4
A14: Martinez-Aguila, Carmen | B14: 33.18 | C14: 33.18
D15: =SUM(B11:C14) -> 296.14
A18: Payroll 3/21/11 | B18: Employee Contribution | C18: Employer Contribution | D18: Amount Due
A19: Crostic, Deanna | B19: 99.4 | C19: 42.6
A20: Darr, Melanie | B20: 23.49 | C20: 23.49
A21: Gandara, Araceli | B21: 20.4 | C21: 20.4
A22: Martinez-Aguila, Carmen | B22: 33.18 | C22: 33.18
D23: =SUM(B19:C22) -> 296.14
A25: Payroll 3/28/11 | B25: Employee Contribution | C25: Employer Contribution | D25: Amount Due
A26: Crostic, Deanna | B26: 99.4 | C26: 42.6
A27: Darr, Melanie | B27: 23.16 | C27: 23.16
A28: Gandara, Araceli | B28: 20.4 | C28: 20.4
A29: Martinez-Aguila, Carmen | B29: 32.97 | C29: 32.97
D30: =SUM(B26:C29) -> 295.06
A32: Balance due March 2011 | D32: =D7+D15+D23+D30 -> 1217.68

Sheet April 2011
A1: Home Protection Associates
A2: Payroll 4/4/11 | B2: employee contribution | C2: Employer Contribution | D2: Amount Due
A3: Crostic, Deanna | B3: 99.4 | C3: 42.6
A4: Darr, Melanie | B4: 23.49 | C4: 23.49
A5: Gandara, Araceli | B5: 20.4 | C5: 20.4
A6: Martinez-Aguila, Carmen | B6: 33.18 | C6: 33.18
D7: =SUM(B3:C6) -> 296.14
A10: Payroll 4/11/11 | B10: Employee Contribution | C10: Employer Contribution | D10: Amount Due
A11: Crostic, Deanna | B11: 124.25 | C11: 53.25
A12: Darr, Melanie | B12: 23.49 | C12: 23.49
A13: Gandara, Araceli | B13: 20.4 | C13: 20.4
A14: Martinez-Aguila, Carmen | B14: 33.18 | C14: 33.18
D15: =SUM(B11:C14) -> 331.64
A18: Payroll 4/18/11 | B18: Employee Contribution | C18: Employer Contribution | D18: Amount Due
A19: Crostic, Deanna | B19: 124.25 | C19: 53.25
A20: Darr, Melanie | B20: 19.58 | C20: 19.58
A21: Gandara, Araceli | B21: 20.4 | C21: 20.4
A22: Martinez-Aguila, Carmen | B22: 20.4 | C22: 20.4
D23: =SUM(B19:C22) -> 298.26
A25: Payroll 4/25/11 | B25: Employee Contribution | C25: Employer Contribution | D25: Amount Due
A26: Crostic, Deanna | B26: 99.4 | C26: 42.6
A27: Darr, Melanie | B27: 23.49 | C27: 23.49
A28: Gandara, Araceli | B28: 20.4 | C28: 20.4
A29: Martinez-Aguila, Carmen
D30: =SUM(B26:C29) -> 229.78
A32: Balance due April 2011 | D32: =D7+D15+D23+D30 -> 1155.82

Sheet May 2011
A1: Home Protection Associates
A2: Payroll 5/7/11 | B2: employee contribution | C2: Employer Contribution | D2: Amount Due
A3: Crostic, Deanna | B3: 99.4 | C3: 42.6
A4: Darr, Melanie | B4: 21.86 | C4: 21.86
A5: Gandara, Araceli | B5: 20.4 | C5: 20.4
A6: Martinez-Aguila, Carmen | B6: 33.18 | C6: 33.18
D7: =SUM(B3:C6) -> 292.88
A10: Payroll 5/14/11 | B10: Employee Contribution | C10: Employer Contribution | D10: Amount Due
A11: Crostic, Deanna | B11: 99.4 | C11: 42.6
A12: Darr, Melanie | B12: 23.49 | C12: 23.49
A13: Gandara, Araceli | B13: 20.4 | C13: 20.4
A14: Martinez-Aguila, Carmen | B14: 33.18 | C14: 33.18
D15: =SUM(B11:C14) -> 296.14
A18: Payroll 5/21/11 | B18: Employee Contribution | C18: Employer Contribution | D18: Amount Due
A19: Crostic, Deanna | B19: 99.4 | C19: 42.6
A20: Darr, Melanie | B20: 23.33 | C20: 23.33
A21: Gandara, Araceli | B21: 19.89 | C21: 19.89
A22: Martinez-Aguila, Carmen | B22: 33.18 | C22: 33.18
D23: =SUM(B19:C22) -> 294.8
A25: Payroll5/28/11 | B25: Employee Contribution | C25: Employer Contribution | D25: Amount Due
A26: Crostic, Deanna | B26: 124.25 | C26: 53.25
A27: Darr, Melanie | B27: 23.49 | C27: 23.49
A28: Gandara, Araceli | B28: 20.4 | C28: 20.4
A29: Martinez-Aguila, Carmen | B29: 33.18 | C29: 33.18
D30: =SUM(B26:C29) -> 331.64
A32: Balance due May 2011 | D32: =D7+D15+D23+D30 -> 1215.46

Sheet June 2011
A1: Home Protection Associates
A2: Payroll 6/4/11 | B2: employee contribution | C2: Employer Contribution | D2: Amount Due
A3: Crostic, Deanna | B3: 99.4 | C3: 42.6
A4: Darr, Melanie | B4: 23.49 | C4: 23.49
A5: Gandara, Araceli | B5: 20.4 | C5: 20.4
A6: Martinez-Aguila, Carmen | B6: 33.18 | C6: 33.18
D7: =SUM(B3:C6) -> 296.14
A10: Payroll 6/11/11 | B10: Employee Contribution | C10: Employer Contribution | D10: Amount Due
A11: Crostic, Deanna | B11: 99.4 | C11: 42.6
A12: Darr, Melanie | B12: 23.49 | C12: 23.49
A13: Gandara, Araceli | B13: 20.4 | C13: 20.4
A14: Martinez-Aguila, Carmen | B14: 33.18 | C14: 33.18
D15: =SUM(B11:C14) -> 296.14
A18: Payroll6/18/11 | B18: Employee Contribution | C18: Employer Contribution | D18: Amount Due
A19: Crostic, Deanna | B19: 99.4 | C19: 42.6
A20: Darr, Melanie | B20: 22.19 | C20: 22.19
A21: Gandara, Araceli | B21: 20.4 | C21: 20.4
A22: Martinez-Aguila, Carmen | B22: 32.97 | C22: 32.97
D23: =SUM(B19:C22) -> 293.12
A25: Payroll 6/25/11 | B25: Employee Contribution | C25: Employer Contribution | D25: Amount Due
A26: Crostic, Deanna | B26: 99.4 | C26: 42.6
A27: Darr, Melanie | B27: 23.49 | C27: 23.49
A28: Gandara, Araceli | B28: 20.4 | C28: 20.4
A29: Martinez-Aguila, Carmen | B29: 33.18 | C29: 33.18
D30: =SUM(B26:C29) -> 296.14
A32: Balance due June 2011 | D32: =D7+D15+D23+D30 -> 1181.54

Sheet July 2011
A1: Home Protection Associates
A2: Payroll 7/1/11 | B2: employee contribution | C2: Employer Contribution | D2: Amount Due
A3: Crostic, Deanna | B3: 99.4 | C3: 42.6
A4: Darr, Melanie | B4: 20.88 | C4: 20.88
A5: Gandara, Araceli | B5: 19.38 | C5: 19.38
A6: Martinez-Aguila, Carmen | B6: 33.18 | C6: 33.18
D7: =SUM(B3:C6) -> 288.88
A10: Payroll 7/11/11 | B10: Employee Contribution | C10: Employer Contribution | D10: Amount Due
A11: Crostic, Deanna | B11: 119.28 | C11: 51.12
A12: Darr, Melanie | B12: 23.49 | C12: 23.49
A13: Gandara, Araceli | B13: 16.32 | C13: 16.32
A14: Martinez-Aguila, Carmen | B14: 33.18 | C14: 33.18
D15: =SUM(B11:C14) -> 316.38
A18: Payroll 7/18/11 | B18: Employee Contribution | C18: Employer Contribution | D18: Amount Due
A19: Crostic, Deanna | B19: 99.4 | C19: 42.6
A20: Darr, Melanie | B20: 22.84 | C20: 22.84
A21: Gandara, Araceli | B21: 18.36 | C21: 18.36
A22: Martinez-Aguila, Carmen | B22: 33.18 | C22: 33.18
D23: =SUM(B19:C22) -> 290.76
A25: Payroll 7/25/11 | B25: Employee Contribution | C25: Employer Contribution | D25: Amount Due
A26: Crostic, Deanna | B26: 99.4 | C26: 42.6
A27: Darr, Melanie | B27: 23.49 | C27: 23.49
A28: Gandara, Araceli | B28: 18.36 | C28: 18.36
A29: Martinez-Aguila, Carmen | B29: 33.18 | C29: 33.18
D30: =SUM(B26:C29) -> 292.06
A32: Balance due July 2011 | D32: =D7+D15+D23+D30 -> 1188.08

Sheet August 2011 
A1: Home Protection Associates
A2: Payroll 8/8/11 | B2: employee contribution | C2: Employer Contribution | D2: Amount Due
A3: Crostic, Deanna | B3: 122.64 | C3: 52.56
A4: Darr, Melanie | B4: 24.57 | C4: 24.57
A5: Gandara, Araceli | B5: 19.44 | C5: 19.44
A6: Martinez-Aguila, Carmen | B6: 34.38 | C6: 34.38
D7: =SUM(B3:C6) -> 331.98
A10: Payroll 8/15/11 | B10: Employee Contribution | C10: Employer Contribution | D10: Amount Due
A11: Crostic, Deanna | B11: 102.2 | C11: 43.8
A12: Darr, Melanie | B12: 24.23 | C12: 24.23
A13: Gandara, Araceli | B13: 17.28 | C13: 17.28
A14: Martinez-Aguila, Carmen | B14: 34.38 | C14: 34.38
D15: =SUM(B11:C14) -> 297.78
A18: Payroll 8/22/11 | B18: Employee Contribution | C18: Employer Contribution | D18: Amount Due
A19: Crostic, Deanna | B19: 102.2 | C19: 102.2
A20: Darr, Melanie | B20: 24.57 | C20: 24.57
A21: Gandara, Araceli | B21: 21.6 | C21: 21.6
A22: Martinez-Aguila, Carmen | B22: 34.38 | C22: 34.38
D23: =SUM(B19:C22) -> 365.5
A25: Payroll 8/29/11 | B25: Employee Contribution | C25: Employer Contribution | D25: Amount Due
A26: Crostic, Deanna | B26: 102.2 | C26: 43.8
A27: Darr, Melanie | B27: 24.57 | C27: 24.57
A28: Gandara, Araceli | B28: 21.6 | C28: 21.6
A29: Martinez-Aguila, Carmen | B29: 34.38 | C29: 34.38
D30: =SUM(B26:C29) -> 307.1
A32: Balance due Aug 2011 | D32: =D7+D15+D23+D30 -> 1302.36

Sheet Sept 2011 
A1: Home Protection Associates
A2: Payroll 9/3/11 | B2: employee contribution | C2: Employer Contribution | D2: Amount Due
A3: Crostic, Deanna | B3: 102.2 | C3: 43.8
A4: Darr, Melanie | B4: 24.57 | C4: 24.57
A5: Gandara, Araceli | B5: 19.44 | C5: 19.44
A6: Martinez-Aguila, Carmen | B6: 34.38 | C6: 34.38
D7: =SUM(B3:C6) -> 302.78
A10: Payroll 9/10/11 | B10: Employee Contribution | C10: Employer Contribution | D10: Amount Due
A11: Crostic, Deanna | B11: 102.2 | C11: 43.8
A12: Darr, Melanie | B12: 24.57 | C12: 24.57
A13: Gandara, Araceli | B13: 21.6 | C13: 21.6
A14: Martinez-Aguila, Carmen | B14: 34.38 | C14: 34.38
D15: =SUM(B11:C14) -> 307.1
A18: Payroll 9/17/11 | B18: Employee Contribution | C18: Employer Contribution | D18: Amount Due
A19: Crostic, Deanna | B19: 102.2 | C19: 43.8
A20: Darr, Melanie | B20: 24.57 | C20: 24.57
A21: Gandara, Araceli | B21: 21.6 | C21: 21.6
A22: Martinez-Aguila, Carmen | B22: 34.38 | C22: 34.38
D23: =SUM(B19:C22) -> 307.1
A25: Payroll 9/24/11 | B25: Employee Contribution | C25: Employer Contribution | D25: Amount Due
A26: Crostic, Deanna | B26: 102.2 | C26: 43.8
A27: Darr, Melanie | B27: 24.57 | C27: 24.57
A28: Gandara, Araceli | B28: 21.6 | C28: 21.6
A29: Martinez-Aguila, Carmen | B29: 34.38 | C29: 34.38
D30: =SUM(B26:C29) -> 307.1
A32: Balance due Sept 2011 | D32: =D7+D15+D23+D30 -> 1224.08

Sheet Oct 2011  
A1: Home Protection Associates
A2: Payroll10/1/11 | B2: employee contribution | C2: Employer Contribution | D2: Amount Due
A3: Crostic, Deanna | B3: 102.2 | C3: 43.8
A4: Darr, Melanie | B4: 24.57 | C4: 24.57
A5: Gandara, Araceli | B5: 21.6 | C5: 21.6
A6: Martinez-Aguila, Carmen | B6: 34.38 | C6: 34.38
D7: =SUM(B3:C6) -> 307.1
A10: Payroll 10/8/11 | B10: Employee Contribution | C10: Employer Contribution | D10: Amount Due
A11: Crostic, Deanna | B11: 102.2 | C11: 43.8
A12: Darr, Melanie | B12: 24.57 | C12: 24.57
A13: Gandara, Araceli | B13: 21.6 | C13: 21.6
A14: Martinez-Aguila, Carmen | B14: 34.38 | C14: 34.38
D15: =SUM(B11:C14) -> 307.1
A18: Payroll 10/15/11 | B18: Employee Contribution | C18: Employer Contribution | D18: Amount Due
A19: Crostic, Deanna | B19: 122.64 | C19: 52.56
A20: Darr, Melanie | B20: 24.57 | C20: 24.57
A21: Gandara, Araceli | B21: 21.6 | C21: 21.6
A22: Martinez-Aguila, Carmen | B22: 34.38 | C22: 34.38
D23: =SUM(B19:C22) -> 336.3
A25: Payroll10/22/11 | B25: Employee Contribution | C25: Employer Contribution | D25: Amount Due
A26: Crostic, Deanna | B26: 102.2 | C26: 43.8
A27: Darr, Melanie | B27: 24.57 | C27: 24.57
A28: Gandara, Araceli | B28: 21.6 | C28: 21.6
A29: Martinez-Aguila, Carmen | B29: 35.67 | C29: 35.67
D30: =SUM(B26:C29) -> 309.68
A31: Payroll10/29/11 | B31: Employee Contribution | C31: Employer Contribution | D31: Amount Due
A32: Crostic, Deanna | B32: 102.2 | C32: 43.8
A33: Darr, Melanie | B33: 24.57 | C33: 24.57
A34: Gandara, Araceli | B34: 21.6 | C34: 21.6
A35: Martinez-Aguila, Carmen | B35: 34.38 | C35: 34.38
D36: =SUM(B32:C35) -> 307.1
A38: Total Oct | D38: =D36+D30+D23+D15+D7 -> 1567.28

Sheet Nov 2011
A1: Home Protection Associates
A2: Payroll 11/7/11 | B2: employee contribution | C2: Employer Contribution | D2: Amount Due
A3: Crostic, Deanna | B3: 102.2 | C3: 43.8
A4: Darr, Melanie | B4: 21.84 | C4: 21.84
A5: Gandara, Araceli | B5: 21.6 | C5: 21.6
A6: Martinez-Aguila, Carmen | B6: 34.38 | C6: 34.38
D7: =SUM(B3:C6) -> 301.64
A10: Payroll 11/14/11 | B10: Employee Contribution | C10: Employer Contribution | D10: Amount Due
A11: Crostic, Deanna | B11: 102.2 | C11: 43.8
A12: Darr, Melanie | B12: 24.57 | C12: 24.57
A13: Gandara, Araceli | B13: 21.6 | C13: 21.6
A14: Martinez-Aguila, Carmen | B14: 34.38 | C14: 34.38
D15: =SUM(B11:C14) -> 307.1
A18: Payroll 11/21/11 | B18: Employee Contribution | C18: Employer Contribution | D18: Amount Due
A19: Crostic, Deanna | B19: 102.2 | C19: 43.8
A20: Darr, Melanie | B20: 24.57 | C20: 24.57
A21: Gandara, Araceli | B21: 21.6 | C21: 21.6
A22: Martinez-Aguila, Carmen | B22: 34.38 | C22: 34.38
D23: =SUM(B19:C22) -> 307.1
A25: Payroll 11/28/11 | B25: Employee Contribution | C25: Employer Contribution | D25: Amount Due
A26: Crostic, Deanna | B26: 102.2 | C26: 43.8
A27: Darr, Melanie | B27: 24.57 | C27: 24.57
A28: Gandara, Araceli | B28: 21.6 | C28: 21.6
A29: Martinez-Aguila, Carmen | B29: 34.38 | C29: 34.38
D30: =SUM(B26:C29) -> 307.1
A31: Payroll | B31: Employee Contribution | C31: Employer Contribution | D31: Amount Due
A32: Crostic, Deanna
A33: Darr, Melanie
A34: Gandara, Araceli
A35: Martinez-Aguila, Carmen
D36: =SUM(B32:C35) -> 0
A38: Total Nov | D38: =D36+D30+D23+D15+D7 -> 1222.94

Sheet Dec 2011 
A1: Home Protection Associates
A2: Payroll 12/5/11 | B2: employee contribution | C2: Employer Contribution | D2: Amount Due
A3: Crostic, Deanna | B3: 102.2 | C3: 43.8
A4: Darr, Melanie | B4: 24.57 | C4: 24.57
A5: Gandara, Araceli | B5: 21.6 | C5: 21.6
A6: Martinez-Aguila, Carmen | B6: 34.38 | C6: 34.38
D7: =SUM(B3:C6) -> 307.1
A10: Payroll 12/12/11 | B10: Employee Contribution | C10: Employer Contribution | D10: Amount Due
A11: Crostic, Deanna | B11: 102.2 | C11: 43.8
A12: Darr, Melanie | B12: 24.57 | C12: 24.57
A13: Gandara, Araceli | B13: 17.28 | C13: 17.28
A14: Martinez-Aguila, Carmen | B14: 34.38 | C14: 34.38
D15: =SUM(B11:C14) -> 298.46
A18: Payroll 12/19/11 | B18: Employee Contribution | C18: Employer Contribution | D18: Amount Due
A19: Crostic, Deanna | B19: 102.2 | C19: 43.8
A20: Darr, Melanie | B20: 24.57 | C20: 24.57
A21: Gandara, Araceli | B21: 21.6 | C21: 21.6
A22: Martinez-Aguila, Carmen | B22: 34.38 | C22: 34.38
D23: =SUM(B19:C22) -> 307.1
A25: Payroll 12/24/11 | B25: Employee Contribution | C25: Employer Contribution | D25: Amount Due
A26: Crostic, Deanna | B26: 102.2 | C26: 43.8
A27: Darr, Melanie | B27: 24.23 | C27: 24.23
A28: Gandara, Araceli | B28: 21.6 | C28: 21.6
A29: Martinez-Aguila, Carmen | B29: 34.38 | C29: 34.38
D30: =SUM(B26:C29) -> 306.42
A31: Payroll 12/31/11 | B31: Employee Contribution | C31: Employer Contribution | D31: Amount Due
A32: Crostic, Deanna | B32: 102.2 | C32: 43.8
A33: Darr, Melanie | B33: 27.3 | C33: 27.3
A34: Gandara, Araceli | B34: 21.6 | C34: 21.6
A35: Martinez-Aguila, Carmen | B35: 34.38 | C35: 34.38
D36: =SUM(B32:C35) -> 312.56
A38: Total Dec | D38: =D36+D30+D23+D15+D7 -> 1531.64

Sheet Jan 2012
A1: Home Protection Associates
A2: Payroll 1/9/2012 | B2: employee contribution | C2: Employer Contribution | D2: Amount Due
A3: Crostic, Deanna | B3: 102.2 | C3: 43.8
A4: Darr, Melanie | B4: 24.57 | C4: 24.57
A5: Gandara, Araceli | B5: 17.28 | C5: 17.28
A6: Martinez-Aguila, Carmen | B6: 34.38 | C6: 34.38
D7: =SUM(B3:C6) -> 298.46
A10: Payroll 1/13/2012 | B10: Employee Contribution | C10: Employer Contribution | D10: Amount Due
A11: Crostic, Deanna | B11: 102.2 | C11: 43.8
A12: Darr, Melanie | B12: 24.57 | C12: 24.57
A13: Gandara, Araceli | B13: 21.6 | C13: 21.6
A14: Martinez-Aguila, Carmen | B14: 34.38 | C14: 34.38
D15: =SUM(B11:C14) -> 307.1
A18: Payroll 1/23/2012 | B18: Employee Contribution | C18: Employer Contribution | D18: Amount Due
A19: Crostic, Deanna | B19: 102.2 | C19: 43.8
A20: Darr, Melanie | B20: 24.57 | C20: 24.57
A21: Gandara, Araceli | B21: 21.6 | C21: 21.6
A22: Martinez-Aguila, Carmen | B22: 34.38 | C22: 34.38
D23: =SUM(B19:C22) -> 307.1
A25: Payroll 1/30/2012 | B25: Employee Contribution | C25: Employer Contribution | D25: Amount Due
A26: Crostic, Deanna | B26: 102.2 | C26: 43.8
A27: Darr, Melanie | B27: 24.57 | C27: 24.57
A28: Gandara, Araceli | B28: 21.6 | C28: 21.6
A29: Martinez-Aguila, Carmen | B29: 34.38 | C29: 34.38
D30: =SUM(B26:C29) -> 307.1
A31: Payroll 12/31/11 | B31: Employee Contribution | C31: Employer Contribution | D31: Amount Due
A32: Crostic, Deanna | B32: 102.2 | C32: 43.8
A33: Darr, Melanie | B33: 27.3 | C33: 27.3
A34: Gandara, Araceli | B34: 21.6 | C34: 21.6
A35: Martinez-Aguila, Carmen | B35: 34.38 | C35: 34.38
D36: =SUM(B32:C35) -> 312.56
A38: Total Jan 2012 | D38: =D36+D30+D23+D15+D7 -> 1532.32

Sheet Feb 2012 
A1: Home Protection Associates
A2: Payroll 2/6/2012 | B2: employee contribution | C2: Employer Contribution | D2: Amount Due
A3: Crostic, Deanna | B3: 102.2 | C3: 43.8
A4: Darr, Melanie | B4: 24.57 | C4: 24.57
A5: Gandara, Araceli | B5: 21.6 | C5: 21.6
A6: Martinez-Aguila, Carmen | B6: 34.38 | C6: 34.38
D7: =SUM(B3:C6) -> 307.1
A10: Payroll 2/13/2012 | B10: Employee Contribution | C10: Employer Contribution | D10: Amount Due
A11: Crostic, Deanna | B11: 102.2 | C11: 43.8
A12: Darr, Melanie | B12: 24.57 | C12: 24.57
A13: Gandara, Araceli | B13: 21.6 | C13: 21.6
A14: Martinez-Aguila, Carmen | B14: 34.38 | C14: 34.38
D15: =SUM(B11:C14) -> 307.1
A18: Payroll 2/20/2012 | B18: Employee Contribution | C18: Employer Contribution | D18: Amount Due
A19: Crostic, Deanna | B19: 102.2 | C19: 43.8
A20: Darr, Melanie | B20: 24.57 | C20: 24.57
A21: Gandara, Araceli | B21: 19.44 | C21: 19.44
A22: Martinez-Aguila, Carmen | B22: 34.38 | C22: 34.38
D23: =SUM(B19:C22) -> 302.78
A25: Payroll 2/27/2012 | B25: Employee Contribution | C25: Employer Contribution | D25: Amount Due
A26: Crostic, Deanna | B26: 102.2 | C26: 43.8
A27: Darr, Melanie | B27: 24.57 | C27: 24.57
A28: Gandara, Araceli | B28: 21.6 | C28: 21.6
A29: Martinez-Aguila, Carmen | B29: 34.38 | C29: 34.38
D30: =SUM(B26:C29) -> 307.1
A31: Payroll | B31: Employee Contribution | C31: Employer Contribution | D31: Amount Due
A32: Crostic, Deanna
A33: Darr, Melanie
A34: Gandara, Araceli
A35: Martinez-Aguila, Carmen
D36: =SUM(B32:C35) -> 0
A38: Total Feb 2012 | D38: =D36+D30+D23+D15+D7 -> 1224.08

Sheet March 2012
A1: Home Protection Associates
A2: Payroll 3/5/2012 | B2: employee contribution | C2: Employer Contribution | D2: Amount Due
A3: Crostic, Deanna | B3: 102.2 | C3: 43.8
A4: Darr, Melanie | B4: 24.57 | C4: 24.57
A5: Gandara, Araceli | B5: 21.6 | C5: 21.6
A6: Martinez-Aguila, Carmen | B6: 34.38 | C6: 34.38
D7: =SUM(B3:C6) -> 307.1
A10: Payroll 3/12/2012 | B10: Employee Contribution | C10: Employer Contribution | D10: Amount Due
A11: Crostic, Deanna | B11: 102.2 | C11: 43.8
A12: Darr, Melanie | B12: 24.57 | C12: 24.57
A13: Gandara, Araceli | B13: 21.6 | C13: 21.6
A14: Martinez-Aguila, Carmen | B14: 34.38 | C14: 34.38
D15: =SUM(B11:C14) -> 307.1
A18: Payroll 3/19/2012 | B18: Employee Contribution | C18: Employer Contribution | D18: Amount Due
A19: Crostic, Deanna | B19: 102.2 | C19: 43.8
A20: Darr, Melanie | B20: 24.57 | C20: 24.57
A21: Gandara, Araceli | B21: 21.6 | C21: 21.6
A22: Martinez-Aguila, Carmen | B22: 34.38 | C22: 34.38
D23: =SUM(B19:C22) -> 307.1
A25: Payroll 3/26/2012 | B25: Employee Contribution | C25: Employer Contribution | D25: Amount Due
A26: Crostic, Deanna | B26: 102.2 | C26: 43.8
A27: Darr, Melanie | B27: 24.57 | C27: 24.57
A28: Gandara, Araceli | B28: 21.6 | C28: 21.6
A29: Martinez-Aguila, Carmen | B29: 34.38 | C29: 34.38
D30: =SUM(B26:C29) -> 307.1
A31: Payroll | B31: Employee Contribution | C31: Employer Contribution | D31: Amount Due
A32: Crostic, Deanna
A33: Darr, Melanie
A34: Gandara, Araceli
A35: Martinez-Aguila, Carmen
D36: =SUM(B32:C35) -> 0
A38: Total March 2012 | D38: =D36+D30+D23+D15+D7 -> 1228.4

Sheet April 2012
A1: Home Protection Associates
A2: Payroll 4/2/2012 | B2: employee contribution | C2: Employer Contribution | D2: Amount Due
A3: Crostic, Deanna | B3: 130 | C3: 43.8
A4: Darr, Melanie | B4: 24.57 | C4: 24.57
A5: Gandara, Araceli | B5: 21.6 | C5: 21.6
A6: Martinez-Aguila, Carmen | B6: 34.38 | C6: 34.38
D7: =SUM(B3:C6) -> 334.9
A10: Payroll 4/9/2012 | B10: Employee Contribution | C10: Employer Contribution | D10: Amount Due
A11: Crostic, Deanna | B11: 130 | C11: 43.8
A12: Darr, Melanie | B12: 24.57 | C12: 24.57
A13: Gandara, Araceli | B13: 21.6 | C13: 21.6
A14: Martinez-Aguila, Carmen | B14: 34.38 | C14: 34.38
D15: =SUM(B11:C14) -> 334.9
A18: Payroll 4/16/2012 | B18: Employee Contribution | C18: Employer Contribution | D18: Amount Due
A19: Crostic, Deanna | B19: 130 | C19: 43.8
A20: Darr, Melanie | B20: 24.57 | C20: 24.57
A21: Gandara, Araceli | B21: 21.6 | C21: 21.6
A22: Martinez-Aguila, Carmen | B22: 36.96 | C22: 36.96
D23: =SUM(B19:C22) -> 340.06
A25: Payroll 4/23/2012 | B25: Employee Contribution | C25: Employer Contribution | D25: Amount Due
A26: Crostic, Deanna | B26: 130 | C26: 43.8
A27: Darr, Melanie | B27: 24.57 | C27: 24.57
A28: Gandara, Araceli | B28: 21.6 | C28: 21.6
A29: Martinez-Aguila, Carmen | B29: 35.67 | C29: 35.67
D30: =SUM(B26:C29) -> 337.48
A31: Payroll 4/30/2012 | B31: Employee Contribution | C31: Employer Contribution | D31: Amount Due
A32: Crostic, Deanna | B32: 130 | C32: 43.8
A33: Darr, Melanie | B33: 24.57 | C33: 24.57
A34: Gandara, Araceli | B34: 21.6 | C34: 21.6
A35: Martinez-Aguila, Carmen | B35: 34.38 | C35: 34.38
D36: =SUM(B32:C35) -> 334.9
A38: Total April 2012 | D38: =D36+D30+D23+D15+D7 -> 1682.24

Sheet May 2012
A1: Home Protection Associates
A2: Payroll 5/7/2012 | B2: employee contribution | C2: Employer Contribution | D2: Amount Due
A3: Crostic, Deanna | B3: 130 | C3: 43.8
A4: Darr, Melanie | B4: 24.57 | C4: 24.57
A5: Gandara, Araceli | B5: 21.6 | C5: 21.6
A6: Martinez-Aguila, Carmen | B6: 29.22 | C6: 29.22
D7: =SUM(B3:C6) -> 324.58
A10: Payroll 5/14/2012 | B10: Employee Contribution | C10: Employer Contribution | D10: Amount Due
A11: Crostic, Deanna | B11: 130 | C11: 43.8
A12: Darr, Melanie | B12: 24.57 | C12: 24.57
A13: Gandara, Araceli | B13: 21.6 | C13: 21.6
A14: Martinez-Aguila, Carmen | B14: 34.38 | C14: 34.38
D15: =SUM(B11:C14) -> 334.9
A18: Payroll 5/21/2012 | B18: Employee Contribution | C18: Employer Contribution | D18: Amount Due
A19: Crostic, Deanna | B19: 130 | C19: 43.8
A20: Darr, Melanie | B20: 24.57 | C20: 24.57
A21: Gandara, Araceli | B21: 21.6 | C21: 21.6
A22: Martinez-Aguila, Carmen | B22: 34.38 | C22: 34.38
D23: =SUM(B19:C22) -> 334.9
A25: Payroll 5/25/2012 | B25: Employee Contribution | C25: Employer Contribution | D25: Amount Due
A26: Crostic, Deanna | B26: 130 | C26: 43.8
A27: Darr, Melanie | B27: 24.57 | C27: 24.57
A28: Gandara, Araceli | B28: 21.6 | C28: 21.6
A29: Martinez-Aguila, Carmen | B29: 33.52 | C29: 33.52
D30: =SUM(B26:C29) -> 333.18
A31: Payroll | B31: Employee Contribution | C31: Employer Contribution | D31: Amount Due
A32: Crostic, Deanna
A33: Darr, Melanie
A34: Gandara, Araceli
A35: Martinez-Aguila, Carmen
D36: =SUM(B32:C35) -> 0
A38: Total May 2012 | D38: =D36+D30+D23+D15+D7 -> 1327.56

Sheet June 2012
A1: Home Protection Associates
A2: Payroll 6/4/2012 | B2: employee contribution | C2: Employer Contribution | D2: Amount Due
A3: Crostic, Deanna | B3: 130 | C3: 43.8
A4: Darr, Melanie | B4: 24.57 | C4: 24.57
A5: Gandara, Araceli | B5: 21.6 | C5: 21.6
A6: Martinez-Aguila, Carmen | B6: 34.38 | C6: 34.38
D7: =SUM(B3:C6) -> 334.9
A10: Payroll 6/11/2012 | B10: Employee Contribution | C10: Employer Contribution | D10: Amount Due
A11: Crostic, Deanna | B11: 130 | C11: 43.8
A12: Darr, Melanie | B12: 24.57 | C12: 24.57
A13: Gandara, Araceli | B13: 21.6 | C13: 21.6
A14: Martinez-Aguila, Carmen | B14: 31.8 | C14: 31.8
D15: =SUM(B11:C14) -> 329.74
A18: Payroll 6/18/2012 | B18: Employee Contribution | C18: Employer Contribution | D18: Amount Due
A19: Crostic, Deanna | B19: 130 | C19: 43.8
A20: Darr, Melanie | B20: 24.57 | C20: 24.57
A21: Gandara, Araceli | B21: 21.6 | C21: 21.6
A22: Martinez-Aguila, Carmen | B22: 8.6 | C22: 8.6
D23: =SUM(B19:C22) -> 283.34
A25: Payroll 6/25/2012 | B25: Employee Contribution | C25: Employer Contribution | D25: Amount Due
A26: Crostic, Deanna | B26: 130 | C26: 43.8
A27: Darr, Melanie | B27: 24.57 | C27: 24.57
A28: Gandara, Araceli | B28: 21.6 | C28: 21.6
A29: Martinez-Aguila, Carmen | B29: 8.6 | C29: 8.6
D30: =SUM(B26:C29) -> 283.34
A31: Payroll | B31: Employee Contribution | C31: Employer Contribution | D31: Amount Due
A32: Crostic, Deanna
A33: Darr, Melanie
A34: Gandara, Araceli
A35: Martinez-Aguila, Carmen
D36: =SUM(B32:C35) -> 0
A38: Total June 2012 | D38: =D36+D30+D23+D15+D7 -> 1231.32

Sheet July 2012
A1: Home Protection Associates
A2: Payroll 7/2/12 | B2: employee contribution | C2: Employer Contribution | D2: Amount Due
A3: Crostic, Deanna | B3: 130 | C3: 43.8
A4: Darr, Melanie | B4: 24.57 | C4: 24.57
A5: Gandara, Araceli | B5: 21.6 | C5: 21.6
A6: Martinez-Aguila, Carmen | B6: 18.91 | C6: 18.91
D7: =SUM(B3:C6) -> 303.96
A10: Payroll 7/9/12 | B10: Employee Contribution | C10: Employer Contribution | D10: Amount Due
A11: Crostic, Deanna | B11: 130 | C11: 43.8
A12: Darr, Melanie | B12: 24.57 | C12: 24.57
A13: Gandara, Araceli | B13: 21.6 | C13: 21.6
A14: Martinez-Aguila, Carmen | B14: 17.19 | C14: 17.19
D15: =SUM(B11:C14) -> 300.52
A18: Payroll 7/16/12 | B18: Employee Contribution | C18: Employer Contribution | D18: Amount Due
A19: Crostic, Deanna | B19: 130 | C19: 43.8
A20: Darr, Melanie | B20: 24.57 | C20: 24.57
A21: Gandara, Araceli | B21: 21.6 | C21: 21.6
A22: Martinez-Aguila, Carmen | B22: 17.19 | C22: 17.19
D23: =SUM(B19:C22) -> 300.52
A25: Payroll 7/23/12 | B25: Employee Contribution | C25: Employer Contribution | D25: Amount Due
A26: Crostic, Deanna | B26: 130 | C26: 43.8
A27: Darr, Melanie | B27: 24.57 | C27: 24.57
A28: Gandara, Araceli | B28: 21.6 | C28: 21.6
A29: Martinez-Aguila, Carmen | B29: 33.52 | C29: 33.52
D30: =SUM(B26:C29) -> 333.18
A31: Payroll 7/30/12 | B31: Employee Contribution | C31: Employer Contribution | D31: Amount Due
A32: Crostic, Deanna | B32: 130 | C32: 43.8
A33: Darr, Melanie | B33: 24.57 | C33: 24.57
A34: Gandara, Araceli | B34: 21.6 | C34: 21.6
A35: Martinez-Aguila, Carmen | B35: 34.38 | C35: 34.38
D36: =SUM(B32:C35) -> 334.9
A38: Total July 2012 | D38: =D36+D30+D23+D15+D7 -> 1573.08

Sheet Aug 2012
A1: Home Protection Associates
A2: Payroll 8/6/12/12 | B2: employee contribution | C2: Employer Contribution | D2: Amount Due
A3: Crostic, Deanna | B3: 130 | C3: 43.8
A4: Darr, Melanie | B4: 24.57 | C4: 24.57
A5: Gandara, Araceli | B5: 21.6 | C5: 21.6
A6: Martinez-Aguila, Carmen | B6: 34.38 | C6: 34.38
D7: =SUM(B3:C6) -> 334.9
A10: Payroll 8/13/12 | B10: Employee Contribution | C10: Employer Contribution | D10: Amount Due
A11: Crostic, Deanna | B11: 130 | C11: 43.8
A12: Darr, Melanie | B12: 24.57 | C12: 24.57
A13: Gandara, Araceli | B13: 21.6 | C13: 21.6
A14: Martinez-Aguila, Carmen | B14: 34.38 | C14: 34.38
D15: =SUM(B11:C14) -> 334.9
A18: Payroll 8/20/12 | B18: Employee Contribution | C18: Employer Contribution | D18: Amount Due
A19: Crostic, Deanna | B19: 130 | C19: 43.8
A20: Darr, Melanie | B20: 24.57 | C20: 24.57
A21: Gandara, Araceli | B21: 18.9 | C21: 18.9
A22: Martinez-Aguila, Carmen | B22: 34.38 | C22: 34.38
D23: =SUM(B19:C22) -> 329.5
A25: Payroll 8/27/12 | B25: Employee Contribution | C25: Employer Contribution | D25: Amount Due
A26: Crostic, Deanna | B26: 130 | C26: 43.8
A27: Darr, Melanie | B27: 24.57 | C27: 24.57
A28: Gandara, Araceli | B28: 5.4 | C28: 5.4
A29: Martinez-Aguila, Carmen | B29: 34.38 | C29: 34.38
D30: =SUM(B26:C29) -> 302.5
A31: Payroll 8/31/12 | B31: Employee Contribution | C31: Employer Contribution | D31: Amount Due
A32: Crostic, Deanna | B32: 130 | C32: 43.8
A33: Darr, Melanie | B33: 26.97 | C33: 26.97
A34: Gandara, Araceli | B34: 19.68 | C34: 19.68
A35: Martinez-Aguila, Carmen | B35: 36.78 | C35: 36.78
D36: =SUM(B32:C35) -> 340.66
A38: Total Aug 2012 | D38: =D36+D30+D23+D15+D7 -> 1642.46

Sheet Sept 2012 
A1: Home Protection Associates
A2: Payroll9/1/12 | B2: employee contribution | C2: Employer Contribution | D2: Amount Due
A3: Crostic, Deanna | B3: 130 | C3: 46.2
A4: Darr, Melanie | B4: 26.97 | C4: 26.97
A5: Gandara, Araceli | B5: 27.56 | C5: 27.56
A6: Martinez-Aguila, Carmen | B6: 36.78 | C6: 36.78
D7: =SUM(B3:C6) -> 358.82
A10: Payroll 9/8/12 | B10: Employee Contribution | C10: Employer Contribution | D10: Amount Due
A11: Crostic, Deanna | B11: 130 | C11: 44.4
A12: Darr, Melanie | B12: 25.11 | C12: 25.11
A13: Gandara, Araceli | B13: 22.2 | C13: 22.2
A14: Martinez-Aguila, Carmen | B14: 34.98 | C14: 34.98
D15: =SUM(B11:C14) -> 338.98
A18: Payroll 9/15/12 | B18: Employee Contribution | C18: Employer Contribution | D18: Amount Due
A19: Crostic, Deanna | B19: 130 | C19: 44.4
A20: Darr, Melanie | B20: 25.11 | C20: 25.11
A21: Gandara, Araceli | B21: 22.2 | C21: 22.2
A22: Martinez-Aguila, Carmen | B22: 34.98 | C22: 34.98
D23: =SUM(B19:C22) -> 338.98
A25: Payroll 9/24/12 | B25: Employee Contribution | C25: Employer Contribution | D25: Amount Due
A26: Crostic, Deanna | B26: 130 | C26: 44.4
A27: Darr, Melanie | B27: 25.11 | C27: 25.11
A28: Gandara, Araceli | B28: 22.2 | C28: 22.2
A29: Martinez-Aguila, Carmen | B29: 27.98 | C29: 27.98
D30: =SUM(B26:C29) -> 324.98
A31: Payroll | B31: Employee Contribution | C31: Employer Contribution | D31: Amount Due
A32: Crostic, Deanna
A33: Darr, Melanie
A34: Gandara, Araceli
A35: Martinez-Aguila, Carmen
D36: =SUM(B32:C35) -> 0
A38: Total | D38: =D36+D30+D23+D15+D7 -> 1361.76

Sheet Oct  2012
A1: Home Protection Associates
A2: Payroll 10/05/12 | B2: employee contribution | C2: Employer Contribution | D2: Amount Due
A3: Crostic, Deanna | B3: 130 | C3: 44.4
A4: Darr, Melanie | B4: 25.11 | C4: 25.11
A5: Gandara, Araceli | B5: 21.65 | C5: 21.5
A6: Martinez-Aguila, Carmen | B6: 34.98 | C6: 34.98
D7: =SUM(B3:C6) -> 337.73
A10: Payroll 10/15/12 | B10: Employee Contribution | C10: Employer Contribution | D10: Amount Due
A11: Crostic, Deanna | B11: 130 | C11: 44.4
A12: Darr, Melanie | B12: 25.11 | C12: 25.11
A13: Gandara, Araceli | B13: 22.2 | C13: 22.2
A14: Martinez-Aguila, Carmen | B14: 31.92 | C14: 31.92
D15: =SUM(B11:C14) -> 332.86
A18: Payroll 10/22/12 | B18: Employee Contribution | C18: Employer Contribution | D18: Amount Due
A19: Crostic, Deanna | B19: 130 | C19: 44.4
A20: Darr, Melanie | B20: 25.11 | C20: 25.11
A21: Gandara, Araceli | B21: 22.2 | C21: 22.2
A22: Martinez-Aguila, Carmen | B22: 34.98 | C22: 34.98
D23: =SUM(B19:C22) -> 338.98
A25: Payroll 10/29/12 | B25: Employee Contribution | C25: Employer Contribution | D25: Amount Due
A26: Crostic, Deanna | B26: 130 | C26: 44.4
A27: Darr, Melanie | B27: 25.11 | C27: 25.11
A28: Gandara, Araceli | B28: 22.2 | C28: 22.2
A29: Martinez-Aguila, Carmen | B29: 34.98 | C29: 34.98
D30: =SUM(B26:C29) -> 338.98
A31: Payroll | B31: Employee Contribution | C31: Employer Contribution | D31: Amount Due
A32: Crostic, Deanna
A33: Darr, Melanie
A34: Gandara, Araceli
A35: Martinez-Aguila, Carmen
D36: =SUM(B32:C35) -> 0
A38: Total | D38: =D36+D30+D23+D15+D7 -> 1348.55

Sheet Nov 2012
A1: Home Protection Associates
A2: Payroll 11/5/12 | B2: employee contribution | C2: Employer Contribution | D2: Amount Due
A3: Crostic, Deanna | B3: 130 | C3: 44.4
A4: Darr, Melanie | B4: 25.11 | C4: 25.11
A5: Gandara, Araceli | B5: 22.2 | C5: 22.2
A6: Martinez-Aguila, Carmen | B6: 34.98 | C6: 34.98
D7: =SUM(B3:C6) -> 338.98
A10: Payroll 11/9/12 | B10: Employee Contribution | C10: Employer Contribution | D10: Amount Due
A11: Crostic, Deanna | B11: 130 | C11: 44.4
A12: Darr, Melanie | B12: 25.11 | C12: 25.11
A13: Gandara, Araceli | B13: 22.2 | C13: 22.2
A14: Martinez-Aguila, Carmen | B14: 34.98 | C14: 34.98
D15: =SUM(B11:C14) -> 338.98
A18: Payroll 11/19/12 | B18: Employee Contribution | C18: Employer Contribution | D18: Amount Due
A19: Crostic, Deanna | B19: 130 | C19: 44.4
A20: Darr, Melanie | B20: 25.11 | C20: 25.11
A21: Gandara, Araceli | B21: 22.2 | C21: 22.2
A22: Martinez-Aguila, Carmen | B22: 32.79 | C22: 32.79
D23: =SUM(B19:C22) -> 334.6
A25: Payroll 11/24/12 | B25: Employee Contribution | C25: Employer Contribution | D25: Amount Due
A26: Crostic, Deanna | B26: 130 | C26: 44.4
A27: Darr, Melanie | B27: 25.11 | C27: 25.11
A28: Gandara, Araceli | B28: 22.2 | C28: 22.2
A29: Martinez-Aguila, Carmen | B29: 34.98 | C29: 34.98
D30: =SUM(B26:C29) -> 338.98
A31: Payroll | B31: Employee Contribution | C31: Employer Contribution | D31: Amount Due
A32: Crostic, Deanna
A33: Darr, Melanie
A34: Gandara, Araceli
A35: Martinez-Aguila, Carmen
D36: =SUM(B32:C35) -> 0
A38: Total | D38: =D36+D30+D23+D15+D7 -> 1351.54

Sheet Dec 2012
A1: Home Protection Associates
A2: Payroll 12/3/12 | B2: employee contribution | C2: Employer Contribution | D2: Amount Due
A3: Crostic, Deanna | B3: 130 | C3: 44.4
A4: Darr, Melanie | B4: 25.11 | C4: 25.11
A5: Gandara, Araceli | B5: 22.2 | C5: 22.2
A6: Martinez-Aguila, Carmen | B6: 33.23 | C6: 33.23
D7: =SUM(B3:C6) -> 335.48
A10: Payroll 12/17/12 | B10: Employee Contribution | C10: Employer Contribution | D10: Amount Due
A11: Crostic, Deanna | B11: 130 | C11: 44.4
A12: Darr, Melanie | B12: 25.11 | C12: 25.11
A13: Gandara, Araceli | B13: 22.2 | C13: 22.2
A14: Martinez-Aguila, Carmen | B14: 34.54 | C14: 34.54
D15: =SUM(B11:C14) -> 338.1
A18: Payroll 12/24/12 | B18: Employee Contribution | C18: Employer Contribution | D18: Amount Due
A19: Crostic, Deanna | B19: 130 | C19: 44.4
A20: Darr, Melanie | B20: 25.11 | C20: 25.11
A21: Gandara, Araceli | B21: 22.2 | C21: 22.2
A22: Martinez-Aguila, Carmen | B22: 34.98 | C22: 34.98
D23: =SUM(B19:C22) -> 338.98
A25: Payroll 12/31/12 | B25: Employee Contribution | C25: Employer Contribution | D25: Amount Due
A26: Crostic, Deanna | B26: 130 | C26: 44.4
A27: Darr, Melanie | B27: 25.11 | C27: 25.11
A28: Gandara, Araceli | B28: 19.99 | C28: 19.99
A29: Martinez-Aguila, Carmen | B29: 31.48 | C29: 31.48
D30: =SUM(B26:C29) -> 327.56
A31: Payroll | B31: Employee Contribution | C31: Employer Contribution | D31: Amount Due
A32: Crostic, Deanna
A33: Darr, Melanie
A34: Gandara, Araceli
A35: Martinez-Aguila, Carmen
D36: =SUM(B32:C35) -> 0
A38: Total | D38: =D36+D30+D23+D15+D7 -> 1340.12

Sheet Jan 2013
A1: Home Protection Associates
A2: Payroll 1/7/13 | B2: employee contribution | C2: Employer Contribution | D2: Amount Due
A3: Crostic, Deanna | B3: 130 | C3: 44.4
A4: Darr, Melanie | B4: 25.11 | C4: 25.11
A5: Gandara, Araceli | B5: 19.98 | C5: 19.98
A6: Martinez-Aguila, Carmen | B6: 34.98 | C6: 34.98
D7: =SUM(B3:C6) -> 334.54
A10: Payroll 1/14/13 | B10: Employee Contribution | C10: Employer Contribution | D10: Amount Due
A11: Crostic, Deanna | B11: 130 | C11: 44.4
A12: Darr, Melanie | B12: 13.95 | C12: 13.95
A13: Gandara, Araceli | B13: 22.2 | C13: 22.2
A14: Martinez-Aguila, Carmen | B14: 34.98 | C14: 34.98
D15: =SUM(B11:C14) -> 316.66
A18: Payroll 1/21/13 | B18: Employee Contribution | C18: Employer Contribution | D18: Amount Due
A19: Crostic, Deanna | B19: 130 | C19: 44.4
A20: Darr, Melanie | B20: 17.44 | C20: 17.44
A21: Gandara, Araceli | B21: 22.2 | C21: 22.2
A22: Martinez-Aguila, Carmen | B22: 34.98 | C22: 34.98
D23: =SUM(B19:C22) -> 323.64
A25: Payroll 1/28/13 | B25: Employee Contribution | C25: Employer Contribution | D25: Amount Due
A26: Crostic, Deanna | B26: 130 | C26: 44.4
A27: Darr, Melanie | B27: 22.32 | C27: 22.32
A28: Gandara, Araceli | B28: 22.2 | C28: 22.2
A29: Martinez-Aguila, Carmen | B29: 34.97 | C29: 34.98
D30: =SUM(B26:C29) -> 333.39
A31: Payroll | B31: Employee Contribution | C31: Employer Contribution | D31: Amount Due
A32: Crostic, Deanna
A33: Darr, Melanie
A34: Gandara, Araceli
A35: Martinez-Aguila, Carmen
D36: =SUM(B32:C35) -> 0
A38: Total | D38: =D36+D30+D23+D15+D7 -> 1308.23

Sheet Feb 2013
A1: Home Protection Associates
A2: Payroll 2/4/13 | B2: employee contribution | C2: Employer Contribution | D2: Amount Due
A3: Crostic, Deanna | B3: 130 | C3: 44.4
A4: Darr, Melanie | B4: 25.11 | C4: 25.11
A5: Gandara, Araceli | B5: 22.2 | C5: 22.2
A6: Martinez-Aguila, Carmen | B6: 34.98 | C6: 34.98
D7: =SUM(B3:C6) -> 338.98
A10: Payroll 2/11/13 | B10: Employee Contribution | C10: Employer Contribution | D10: Amount Due
A11: Crostic, Deanna | B11: 130 | C11: 44.4
A12: Darr, Melanie | B12: 25.11 | C12: 25.11
A13: Gandara, Araceli | B13: 22.2 | C13: 22.2
